Workbook

Sheet Phương Pháp Định Giá
A1: PHƯƠNG PHÁP ĐỊNH GIÁ V9 - THÁNG 3/2026
A2: Bản Final chi tiết đã check Phương pháp luận & Quy trình - 30Shine_PhuongPhapLuan_FINAL.md
A3: TRIẾT LÝ CỐT LÕI
A4: Tầng 1: WTP → Xác định KHUNG GIÁ [Sàn L ; Trần H]
A5: Tầng 2: CPI × EPI → Xác định VỊ TRÍ trong khung WTP
A6: Công thức: P_min = L + α_low × (H-L), P_max = L + α_high × (H-L)
A8: MA TRẬN CPI × EPI → HỆ SỐ α
A9: CPI \ EPI | B9: EPI Thấp | C9: EPI Trung | D9: EPI Cao
A10: CPI Cao | B10: [0.15 ; 0.35] | C10: [0.25 ; 0.45] | D10: [0.35 ; 0.55]
A11: CPI Trung | B11: [0.25 ; 0.50] | C11: [0.40 ; 0.65] | D11: [0.55 ; 0.80]
A12: CPI Thấp | B12: [0.40 ; 0.65] | C12: [0.55 ; 0.85] | D12: [0.70 ; 1.00]
A14: 4 KỊCH BẢN VẬN HÀNH
A15: KB1: Hút Traffic | B15: =P_min | C15: Thu hút khách mới
A16: KB2: Tăng AOV | B16: =P_max | C16: Tăng doanh thu/margin
A17: KB3: Cân Bằng | B17: =(P_min + P_max) / 2 | C17: Cân bằng lượng và giá
A18: KB4: Giảm Quá Tải | B18: = P_min + 0.85 × (P_max - P_min) | C18: Điều tiết khi quá đông
A20: PHÂN LOẠI CHỈ SỐ
A21: CPI: Cao ≥ 0.6 | Trung 0.4-0.6 | Thấp < 0.4
A22: EPI: Phân loại bằng Percentile P33/P67
A23: EPI P33 = 0.4142, P67 = 0.4540 (trong lần chạy này)

Sheet Cắt Gội
A1: SalonID | B1: Tên Salon | C1: Mã Salon | D1: Tỉnh/TP | E1: Cụm | F1: Loại Cụm | G1: CPI | H1: CPI Level | I1: EPI | J1: EPI Level | K1: Giá Hiện Tại | L1: WTP Sàn (L) | M1: WTP Trần (H) | N1: Hệ Số α_low | O1: Hệ Số α_high | P1: P_min (Khung Dưới) | Q1: P_max (Khung Trên) | R1: Khung Giá Đề Xuất | S1: KB1: Hút Traffic | T1: KB2: Tăng AOV | U1: KB3: Cân Bằng | V1: KB4: Giảm Quá Tải | W1: GDTM Đề xuất - KB2: Tăng AOV | X1: ID dv | Z1: Giá hiện tại | AA1: Chênh lệch giá cũ | AB1: % Chênh lệch
A2: 39 | B2: 151 Cầu Giấy, Q. CG | C2: 151 CG | D2: Hà Nội | E2: 1 | F2: Cụm gốc | G2: 0.6444 | H2: Cao | I2: 0.4063 | J2: Thấp | K2: 150000 | L2: 80000 | M2: 120000 | N2: 0.15 | O2: 0.35 | P2: 86000 | Q2: 94000 | R2: 86k - 94k | S2: 86000 | T2: 94000 | U2: 90000 | V2: 93000 | W2: =T2 | X2: 891 | Y2: =C2&X2 | Z2: =VLOOKUP(Y2,'Data giá Relax hiện tại'!$D:$F,3,0) | AA2: =W2-Z2 | AB2: =AA2/Z2
A3: 146 | B3: 109 Trần Quốc Hoàn | C3: 109 TQH | D3: Hà Nội | E3: 1 | F3: Cụm gốc | G3: 0.6773 | H3: Cao | I3: 0.4359 | J3: Trung | K3: 150000 | L3: 80000 | M3: 120000 | N3: 0.25 | O3: 0.45 | P3: 90000 | Q3: 98000 | R3: 90k - 98k | S3: 90000 | T3: 98000 | U3: 94000 | V3: 97000 | W3: =T3 | X3: 891 | Y3: =C3&X3 | Z3: =VLOOKUP(Y3,'Data giá Relax hiện tại'!$D:$F,3,0) | AA3: =W3-Z3 | AB3: =AA3/Z3
A4: 2 | B4: 346 Khâm Thiên | C4: 346 KT | D4: Hà Nội | E4: 3 | F4: Cụm gốc | G4: 0.6615 | H4: Cao | I4: 0.471 | J4: Cao | K4: 85000 | L4: 100000 | M4: 101000 | N4: 0.35 | O4: 0.55 | P4: 100000 | Q4: 101000 | R4: 100k - 101k | S4: 100000 | T4: 101000 | U4: 100000 | V4: 101000 | W4: 101000 | X4: 891 | Y4: =C4&X4 | Z4: =VLOOKUP(Y4,'Data giá Relax hiện tại'!$D:$F,3,0) | AA4: =W4-Z4 | AB4: =AA4/Z4
A5: 228 | B5: 62 Láng Hạ | C5: 62 LH | D5: Hà Nội | E5: 4 | F5: Cụm gốc | G5: 0.6146 | H5: Cao | I5: 0.4489 | J5: Trung | K5: 135000 | L5: 89000 | M5: 101000 | N5: 0.25 | O5: 0.45 | P5: 92000 | Q5: 94000 | R5: 92k - 94k | S5: 92000 | T5: 94000 | U5: 93000 | V5: 94000 | W5: 98000 | X5: 891 | Y5: =C5&X5 | Z5: =VLOOKUP(Y5,'Data giá Relax hiện tại'!$D:$F,3,0) | AA5: =W5-Z5 | AB5: =AA5/Z5 | AC5: =+4000
A6: 20 | B6: 382 Nguyễn Trãi | C6: 382 NT | D6: Hà Nội | E6: 5 | F6: Cụm gốc | G6: 0.5809 | H6: Trung | I6: 0.5018 | J6: Cao | K6: 100000 | L6: 89000 | M6: 119000 | N6: 0.55 | O6: 0.8 | P6: 106000 | Q6: 113000 | R6: 106k - 113k | S6: 106000 | T6: 113000 | U6: 109000 | V6: 112000 | W6: 112000 | X6: 891 | Y6: =C6&X6 | Z6: =VLOOKUP(Y6,'Data giá Relax hiện tại'!$D:$F,3,0) | AA6: =W6-Z6 | AB6: =AA6/Z6 | AC6: 3000
A7: 210 | B7: 148B Trương Định | C7: 148 TD | D7: Hà Nội | E7: 6 | F7: Cụm gốc | G7: 0.6448 | H7: Cao | I7: 0.361 | J7: Thấp | K7: 135000 | L7: 89000 | M7: 119000 | N7: 0.15 | O7: 0.35 | P7: 94000 | Q7: 100000 | R7: 94k - 100k | S7: 94000 | T7: 100000 | U7: 96000 | V7: 99000 | W7: =T7 | X7: 891 | Y7: =C7&X7 | Z7: =VLOOKUP(Y7,'Data giá Relax hiện tại'!$D:$F,3,0) | AA7: =W7-Z7 | AB7: =AA7/Z7
A8: 250 | B8: 173 Thanh Nhàn | C8: 173 TN | D8: Hà Nội | E8: 6 | F8: Cụm gốc | G8: 0.6493 | H8: Cao | I8: 0.4431 | J8: Trung | K8: 160000 | L8: 89000 | M8: 119000 | N8: 0.25 | O8: 0.45 | P8: 96000 | Q8: 102000 | R8: 96k - 102k | S8: 96000 | T8: 102000 | U8: 100000 | V8: 102000 | W8: =T8 | X8: 891 | Y8: =C8&X8 | Z8: =VLOOKUP(Y8,'Data giá Relax hiện tại'!$D:$F,3,0) | AA8: =W8-Z8 | AB8: =AA8/Z8
A9: 143 | B9: 10 Trần Phú | C9: 10 TP | D9: Hà Nội | E9: 7 | F9: Cụm gốc | G9: 0.6802 | H9: Cao | I9: 0.446 | J9: Trung | K9: 135000 | L9: 90000 | M9: 101000 | N9: 0.25 | O9: 0.45 | P9: 93000 | Q9: 95000 | R9: 93k - 95k | S9: 93000 | T9: 95000 | U9: 94000 | V9: 95000 | W9: =T9 | X9: 891 | Y9: =C9&X9 | Z9: =VLOOKUP(Y9,'Data giá Relax hiện tại'!$D:$F,3,0) | AA9: =W9-Z9 | AB9: =AA9/Z9
A10: 245 | B10: 55A Nguyễn Văn Lộc | C10: 55A NVL | D10: Hà Nội | E10: 7 | F10: Cụm gốc | G10: 0.5529 | H10: Trung | I10: 0.4737 | J10: Cao | K10: 135000 | L10: 90000 | M10: 101000 | N10: 0.55 | O10: 0.8 | P10: 96000 | Q10: 99000 | R10: 96k - 99k | S10: 96000 | T10: 99000 | U10: 97000 | V10: 98000 | W10: =T10 | X10: 891 | Y10: =C10&X10 | Z10: =VLOOKUP(Y10,'Data giá Relax hiện tại'!$D:$F,3,0) | AA10: =W10-Z10 | AB10: =AA10/Z10
A11: 239 | B11: 186 Quang Trung | C11: 186 QT | D11: Hà Nội | E11: 8 | F11: Cụm gốc | G11: 0.5104 | H11: Trung | I11: 0.3918 | J11: Thấp | K11: 110000 | L11: 101000 | M11: 150000 | N11: 0.25 | O11: 0.5 | P11: 113000 | Q11: 126000 | R11: 113k - 126k | S11: 113000 | T11: 126000 | U11: 119000 | V11: 124000 | W11: =105000 | X11: 891 | Y11: =C11&X11 | Z11: =VLOOKUP(Y11,'Data giá Relax hiện tại'!$D:$F,3,0) | AA11: =W11-Z11 | AB11: =AA11/Z11
A12: 231 | B12: 304 Nguyễn Trãi | C12: 304 NT TH | D12: Thanh Hóa | E12: 9 | F12: Cụm gốc | G12: 0.4811 | H12: Trung | I12: 0.4096 | J12: Thấp | K12: 135000 | L12: 100000 | M12: 120000 | N12: 0.25 | O12: 0.5 | P12: 105000 | Q12: 110000 | R12: 105k - 110k | S12: 105000 | T12: 110000 | U12: 108000 | V12: 109000 | W12: =T12 | X12: 891 | Y12: =C12&X12 | Z12: =VLOOKUP(Y12,'Data giá Relax hiện tại'!$D:$F,3,0) | AA12: =W12-Z12 | AB12: =AA12/Z12
A13: 232 | B13: 80 Trần Phú | C13: 80 TP TH | D13: Thanh Hóa | E13: 9 | F13: Cụm gốc | G13: 0.5226 | H13: Trung | I13: 0.4058 | J13: Thấp | K13: 85000 | L13: 100000 | M13: 120000 | N13: 0.25 | O13: 0.5 | P13: 105000 | Q13: 110000 | R13: 105k - 110k | S13: 105000 | T13: 110000 | U13: 108000 | V13: 109000 | W13: =T13 | X13: 891 | Y13: =C13&X13 | Z13: =VLOOKUP(Y13,'Data giá Relax hiện tại'!$D:$F,3,0) | AA13: =W13-Z13 | AB13: =AA13/Z13
A14: 233 | B14: 595 Bà Triệu | C14: 595 BT TH | D14: Thanh Hóa | E14: 9 | F14: Cụm gốc | G14: 0.5387 | H14: Trung | I14: 0.4489 | J14: Trung | K14: 85000 | L14: 100000 | M14: 120000 | N14: 0.4 | O14: 0.65 | P14: 108000 | Q14: 113000 | R14: 108k - 113k | S14: 108000 | T14: 113000 | U14: 110000 | V14: 112000 | W14: 112000 | X14: 891 | Y14: =C14&X14 | Z14: =VLOOKUP(Y14,'Data giá Relax hiện tại'!$D:$F,3,0) | AA14: =W14-Z14 | AB14: =AA14/Z14 | AC14: 4000
A15: 212 | B15: 58 Nguyễn Văn Cừ | C15: 58 NVC NA | D15: Nghệ An | E15: 10 | F15: Cụm gốc | G15: 0.5736 | H15: Trung | I15: 0.3468 | J15: Thấp | K15: 135000 | L15: 80000 | M15: 100000 | N15: 0.25 | O15: 0.5 | P15: 85000 | Q15: 90000 | R15: 85k - 90k | S15: 85000 | T15: 90000 | U15: 88000 | V15: 89000 | W15: =Z15 | X15: 891 | Y15: =C15&X15 | Z15: =VLOOKUP(Y15,'Data giá Relax hiện tại'!$D:$F,3,0) | AA15: =W15-Z15 | AB15: =AA15/Z15
A16: 60 | B16: 80 Phú Lợi | C16: 80 PL BD | D16: Bình Dương | E16: 11 | F16: Cụm gốc | G16: 0.5268 | H16: Trung | I16: 0.366 | J16: Thấp | K16: 85000 | L16: 90000 | M16: 101000 | N16: 0.25 | O16: 0.5 | P16: 93000 | Q16: 96000 | R16: 93k - 96k | S16: 93000 | T16: 96000 | U16: 94000 | V16: 95000 | W16: =T16 | X16: 891 | Y16: =C16&X16 | Z16: =VLOOKUP(Y16,'Data giá Relax hiện tại'!$D:$F,3,0) | AA16: =W16-Z16 | AB16: =AA16/Z16
A17: 52 | B17: 451 Phạm Văn Thuận | C17: 451 PVT | D17: Đồng Nai | E17: 12 | F17: Cụm gốc | G17: 0.5405 | H17: Trung | I17: 0.3055 | J17: Thấp | K17: 135000 | L17: 99000 | M17: 110000 | N17: 0.25 | O17: 0.5 | P17: 102000 | Q17: 104000 | R17: 102k - 104k | S17: 102000 | T17: 104000 | U17: 103000 | V17: 104000 | W17: =S17 | X17: 891 | Y17: =C17&X17 | Z17: =VLOOKUP(Y17,'Data giá Relax hiện tại'!$D:$F,3,0) | AA17: =W17-Z17 | AB17: =AA17/Z17
A18: 247 | B18: 1371 Phạm Văn Thuận | C18: 1371 PVT | D18: Đồng Nai | E18: 12 | F18: Cụm gốc | G18: 0.5754 | H18: Trung | I18: 0.3136 | J18: Thấp | K18: 85000 | L18: 99000 | M18: 110000 | N18: 0.25 | O18: 0.5 | P18: 102000 | Q18: 104000 | R18: 102k - 104k | S18: 102000 | T18: 104000 | U18: 103000 | V18: 104000 | W18: =T18 | X18: 891 | Y18: =C18&X18 | Z18: =VLOOKUP(Y18,'Data giá Relax hiện tại'!$D:$F,3,0) | AA18: =W18-Z18 | AB18: =AA18/Z18
A19: 46 | B19: 483 Thống Nhất | C19: 483 TN | D19: Không xác định | E19: 14 | F19: Cụm gốc | G19: 0.5299 | H19: Trung | I19: 0.4186 | J19: Trung | K19: 150000 | L19: 90000 | M19: 120000 | N19: 0.4 | O19: 0.65 | P19: 102000 | Q19: 110000 | R19: 102k - 110k | S19: 102000 | T19: 110000 | U19: 106000 | V19: 108000 | W19: =S19 | X19: 891 | Y19: =C19&X19 | Z19: =VLOOKUP(Y19,'Data giá Relax hiện tại'!$D:$F,3,0) | AA19: =W19-Z19 | AB19: =AA19/Z19
A20: 12 | B20: 12 Lê Đức Thọ | C20: 12 LDT | D20: Hồ Chí Minh | E20: 15 | F20: Cụm gốc | G20: 0.7678 | H20: Cao | I20: 0.4194 | J20: Trung | K20: 100000 | L20: 94000 | M20: 120000 | N20: 0.25 | O20: 0.45 | P20: 100000 | Q20: 106000 | R20: 100k - 106k | S20: 100000 | T20: 106000 | U20: 103000 | V20: 105000 | W20: =T20 | X20: 891 | Y20: =C20&X20 | Z20: =VLOOKUP(Y20,'Data giá Relax hiện tại'!$D:$F,3,0) | AA20: =W20-Z20 | AB20: =AA20/Z20
A21: 69 | B21: 312 Lê Văn Sỹ | C21: 312 LVS | D21: Không xác định | E21: 16 | F21: Cụm gốc | G21: 0.6377 | H21: Cao | I21: 0.4263 | J21: Trung | K21: 85000 | L21: 90000 | M21: 110000 | N21: 0.25 | O21: 0.45 | P21: 95000 | Q21: 99000 | R21: 95k - 99k | S21: 95000 | T21: 99000 | U21: 97000 | V21: 98000 | W21: =T21 | X21: 891 | Y21: =C21&X21 | Z21: =VLOOKUP(Y21,'Data giá Relax hiện tại'!$D:$F,3,0) | AA21: =W21-Z21 | AB21: =AA21/Z21
A22: 205 | B22: 341 Xô Viết Nghệ Tĩnh | C22: 341 XVNT | D22: Hồ Chí Minh | E22: 17 | F22: Cụm gốc | G22: 0.6578 | H22: Cao | I22: 0.3726 | J22: Thấp | K22: 135000 | L22: 90000 | M22: 110000 | N22: 0.15 | O22: 0.35 | P22: 93000 | Q22: 97000 | R22: 93k - 97k | S22: 93000 | T22: 97000 | U22: 95000 | V22: 96000 | W22: =T22 | X22: 891 | Y22: =C22&X22 | Z22: =VLOOKUP(Y22,'Data giá Relax hiện tại'!$D:$F,3,0) | AA22: =W22-Z22 | AB22: =AA22/Z22
A23: 21 | B23: 575 Âu Cơ | C23: 575 AC | D23: Hồ Chí Minh | E23: 18 | F23: Cụm gốc | G23: 0.644 | H23: Cao | I23: 0.4483 | J23: Trung | K23: 135000 | L23: 90000 | M23: 120000 | N23: 0.25 | O23: 0.45 | P23: 98000 | Q23: 104000 | R23: 98k - 104k | S23: 98000 | T23: 104000 | U23: 100000 | V23: 103000 | W23: =T23 | X23: 891 | Y23: =C23&X23 | Z23: =VLOOKUP(Y23,'Data giá Relax hiện tại'!$D:$F,3,0) | AA23: =W23-Z23 | AB23: =AA23/Z23
A24: 147 | B24: 99 Tân Sơn Nhì | C24: 99 TSN | D24: Hồ Chí Minh | E24: 18 | F24: Cụm gốc | G24: 0.6664 | H24: Cao | I24: 0.4415 | J24: Trung | K24: 85000 | L24: 90000 | M24: 120000 | N24: 0.25 | O24: 0.45 | P24: 98000 | Q24: 104000 | R24: 98k - 104k | S24: 98000 | T24: 104000 | U24: 100000 | V24: 103000 | W24: =T24 | X24: 891 | Y24: =C24&X24 | Z24: =VLOOKUP(Y24,'Data giá Relax hiện tại'!$D:$F,3,0) | AA24: =W24-Z24 | AB24: =AA24/Z24
A25: 193 | B25: 145 Tô Hiến Thành | C25: 145 THT | D25: Hồ Chí Minh | E25: 19 | F25: Cụm gốc | G25: 0.5476 | H25: Trung | I25: 0.4086 | J25: Thấp | K25: 85000 | L25: 80000 | M25: 119000 | N25: 0.25 | O25: 0.5 | P25: 90000 | Q25: 100000 | R25: 90k - 100k | S25: 90000 | T25: 100000 | U25: 95000 | V25: 98000 | W25: =T25 | X25: 891 | Y25: =C25&X25 | Z25: =VLOOKUP(Y25,'Data giá Relax hiện tại'!$D:$F,3,0) | AA25: =W25-Z25 | AB25: =AA25/Z25
A26: 141 | B26: 236 Dương Bá Trạc | C26: 236 DBT | D26: Hồ Chí Minh | E26: 20 | F26: Cụm gốc | G26: 0.6503 | H26: Cao | I26: 0.4151 | J26: Trung | K26: 100000 | L26: 91000 | M26: 120000 | N26: 0.25 | O26: 0.45 | P26: 98000 | Q26: 104000 | R26: 98k - 104k | S26: 98000 | T26: 104000 | U26: 101000 | V26: 103000 | W26: =T26 | X26: 891 | Y26: =C26&X26 | Z26: =VLOOKUP(Y26,'Data giá Relax hiện tại'!$D:$F,3,0) | AA26: =W26-Z26 | AB26: =AA26/Z26
A27: 51 | B27: 420 Huỳnh Tấn Phát | C27: 420 HTP | D27: Hồ Chí Minh | E27: 21 | F27: Cụm gốc | G27: 0.5667 | H27: Trung | I27: 0.42 | J27: Trung | K27: 85000 | L27: 89000 | M27: 101000 | N27: 0.4 | O27: 0.65 | P27: 94000 | Q27: 97000 | R27: 94k - 97k | S27: 94000 | T27: 97000 | U27: 95000 | V27: 96000 | W27: =T27 | X27: 891 | Y27: =C27&X27 | Z27: =VLOOKUP(Y27,'Data giá Relax hiện tại'!$D:$F,3,0) | AA27: =W27-Z27 | AB27: =AA27/Z27
A28: 145 | B28: 237 Nguyễn Thị Thập | C28: 237 NTT | D28: Hồ Chí Minh | E28: 21 | F28: Cụm gốc | G28: 0.7782 | H28: Cao | I28: 0.4394 | J28: Trung | K28: 110000 | L28: 89000 | M28: 101000 | N28: 0.25 | O28: 0.45 | P28: 92000 | Q28: 94000 | R28: 92k - 94k | S28: 92000 | T28: 94000 | U28: 93000 | V28: 94000 | W28: =T28 | X28: 891 | Y28: =C28&X28 | Z28: =VLOOKUP(Y28,'Data giá Relax hiện tại'!$D:$F,3,0) | AA28: =W28-Z28 | AB28: =AA28/Z28
A29: 11 | B29: 8 Châu Văn Liêm | C29: 8 CVL | D29: Hồ Chí Minh | E29: 22 | F29: Cụm mới (cùng tỉnh) | G29: 0.5672 | H29: Trung | I29: 0.3932 | J29: Thấp | K29: 105000 | L29: 99000 | M29: 101000 | N29: 0.25 | O29: 0.5 | P29: 100000 | Q29: 100000 | R29: 100k - 100k | S29: 100000 | T29: 100000 | U29: 100000 | V29: 100000 | W29: 100000 | X29: 891 | Y29: =C29&X29 | Z29: =VLOOKUP(Y29,'Data giá Relax hiện tại'!$D:$F,3,0) | AA29: =W29-Z29 | AB29: =AA29/Z29
A30: 22 | B30: 927 Hậu Giang | C30: 927 HG | D30: Hồ Chí Minh | E30: 22 | F30: Cụm mới (cùng tỉnh) | G30: 0.6209 | H30: Cao | I30: 0.432 | J30: Trung | L30: 99000 | M30: 101000 | N30: 0.25 | O30: 0.45 | P30: 100000 | Q30: 100000 | R30: 100k - 100k | S30: 100000 | T30: 100000 | U30: 100000 | V30: 100000 | W30: =T30 | X30: 891 | Y30: =C30&X30 | Z30: =VLOOKUP(Y30,'Data giá Relax hiện tại'!$D:$F,3,0) | AA30: =W30-Z30 | AB30: =AA30/Z30
A31: 58 | B31: 730 Tỉnh lộ 10 | C31: 730 TL10 | D31: Hồ Chí Minh | E31: 22 | F31: Cụm mới (cùng tỉnh) | G31: 0.5145 | H31: Trung | I31: 0.4168 | J31: Trung | K31: 85000 | L31: 99000 | M31: 101000 | N31: 0.4 | O31: 0.65 | P31: 100000 | Q31: 100000 | R31: 100k - 100k | S31: 100000 | T31: 100000 | U31: 100000 | V31: 100000 | W31: =T31 | X31: 891 | Y31: =C31&X31 | Z31: =VLOOKUP(Y31,'Data giá Relax hiện tại'!$D:$F,3,0) | AA31: =W31-Z31 | AB31: =AA31/Z31
A32: 188 | B32: 190 Hòa Bình | C32: 190 HB | D32: Hồ Chí Minh | E32: 22 | F32: Cụm mới (cùng tỉnh) | G32: 0.6785 | H32: Cao | I32: 0.412 | J32: Thấp | K32: 135000 | L32: 99000 | M32: 101000 | N32: 0.15 | O32: 0.35 | P32: 99000 | Q32: 100000 | R32: 99k - 100k | S32: 99000 | T32: 100000 | U32: 100000 | V32: 100000 | W32: =T32 | X32: 891 | Y32: =C32&X32 | Z32: =VLOOKUP(Y32,'Data giá Relax hiện tại'!$D:$F,3,0) | AA32: =W32-Z32 | AB32: =AA32/Z32
A33: 63 | B33: 29 Hiệp Bình | C33: 29 HB | D33: Hồ Chí Minh | E33: 23 | F33: Cụm mới (cùng tỉnh) | G33: 0.5142 | H33: Trung | I33: 0.379 | J33: Thấp | K33: 150000 | L33: 80000 | M33: 100000 | N33: 0.25 | O33: 0.5 | P33: 85000 | Q33: 90000 | R33: 85k - 90k | S33: 85000 | T33: 90000 | U33: 88000 | V33: 89000 | W33: =Z33 | X33: 891 | Y33: =C33&X33 | Z33: =VLOOKUP(Y33,'Data giá Relax hiện tại'!$D:$F,3,0) | AA33: =W33-Z33 | AB33: =AA33/Z33
A34: 204 | B34: 401/1 Nguyễn Duy Trinh | C34: 401/1 NDT | D34: Hồ Chí Minh | E34: 23 | F34: Cụm mới (cùng tỉnh) | G34: 0.5599 | H34: Trung | I34: 0.3979 | J34: Thấp | K34: 145000 | L34: 80000 | M34: 100000 | N34: 0.25 | O34: 0.5 | P34: 85000 | Q34: 90000 | R34: 85k - 90k | S34: 85000 | T34: 90000 | U34: 88000 | V34: 89000 | W34: =Z34 | X34: 891 | Y34: =C34&X34 | Z34: =VLOOKUP(Y34,'Data giá Relax hiện tại'!$D:$F,3,0) | AA34: =W34-Z34 | AB34: =AA34/Z34
A35: 249 | B35: 1146 Kha Vạn Cân | C35: 1146 KVC | D35: Hồ Chí Minh | E35: 23 | F35: Cụm mới (cùng tỉnh) | G35: 0.6701 | H35: Cao | I35: 0.3804 | J35: Thấp | K35: 150000 | L35: 80000 | M35: 100000 | N35: 0.15 | O35: 0.35 | P35: 83000 | Q35: 87000 | R35: 83k - 87k | S35: 83000 | T35: 87000 | U35: 85000 | V35: 86000 | W35: =Z35 | X35: 891 | Y35: =C35&X35 | Z35: =VLOOKUP(Y35,'Data giá Relax hiện tại'!$D:$F,3,0) | AA35: =W35-Z35 | AB35: =AA35/Z35
A36: 44 | B36: 103 Trần Não | C36: 103 TN | D36: Hồ Chí Minh | E36: 24 | F36: Cụm mới (cùng tỉnh) | G36: 0.5591 | H36: Trung | I36: 0.4948 | J36: Cao | K36: 135000 | L36: 90000 | M36: 101000 | N36: 0.55 | O36: 0.8 | P36: 96000 | Q36: 99000 | R36: 96k - 99k | S36: 96000 | T36: 99000 | U36: 97000 | V36: 98000 | W36: =T36 | X36: 891 | Y36: =C36&X36 | Z36: =VLOOKUP(Y36,'Data giá Relax hiện tại'!$D:$F,3,0) | AA36: =W36-Z36 | AB36: =AA36/Z36
A37: 45 | B37: 25 Tôn Đản | C37: 25 TD | D37: Hồ Chí Minh | E37: 24 | F37: Cụm mới (cùng tỉnh) | G37: 0.6313 | H37: Cao | I37: 0.4649 | J37: Cao | K37: 85000 | L37: 90000 | M37: 101000 | N37: 0.35 | O37: 0.55 | P37: 94000 | Q37: 96000 | R37: 94k - 96k | S37: 94000 | T37: 96000 | U37: 95000 | V37: 96000 | W37: =T37 | X37: 891 | Y37: =C37&X37 | Z37: =VLOOKUP(Y37,'Data giá Relax hiện tại'!$D:$F,3,0) | AA37: =W37-Z37 | AB37: =AA37/Z37
A38: 182 | B38: 186 Đinh Tiên Hoàng | C38: 186 DTH | D38: Hồ Chí Minh | E38: 24 | F38: Cụm mới (cùng tỉnh) | G38: 0.6312 | H38: Cao | I38: 0.4414 | J38: Trung | K38: 145000 | L38: 90000 | M38: 101000 | N38: 0.25 | O38: 0.45 | P38: 93000 | Q38: 95000 | R38: 93k - 95k | S38: 93000 | T38: 95000 | U38: 94000 | V38: 95000 | W38: =T38 | X38: 891 | Y38: =C38&X38 | Z38: =VLOOKUP(Y38,'Data giá Relax hiện tại'!$D:$F,3,0) | AA38: =W38-Z38 | AB38: =AA38/Z38
A39: 47 | B39: 708 Lê Trọng Tấn | C39: 708 LTT | D39: Hồ Chí Minh | E39: 25 | F39: Cụm mới (cùng tỉnh) | G39: 0.5578 | H39: Trung | I39: 0.3585 | J39: Thấp | K39: 85000 | L39: 100000 | M39: 120000 | N39: 0.25 | O39: 0.5 | P39: 105000 | Q39: 110000 | R39: 105k - 110k | S39: 105000 | T39: 110000 | U39: 108000 | V39: 109000 | W39: =T39 | X39: 891 | Y39: =C39&X39 | Z39: =VLOOKUP(Y39,'Data giá Relax hiện tại'!$D:$F,3,0) | AA39: =W39-Z39 | AB39: =AA39/Z39
A40: 61 | B40: 1180 Quang Trung | C40: 1180 QT | D40: Hồ Chí Minh | E40: 25 | F40: Cụm mới (cùng tỉnh) | G40: 0.6374 | H40: Cao | I40: 0.3781 | J40: Thấp | K40: 135000 | L40: 100000 | M40: 120000 | N40: 0.15 | O40: 0.35 | P40: 103000 | Q40: 107000 | R40: 103k - 107k | S40: 103000 | T40: 107000 | U40: 105000 | V40: 106000 | W40: =T40 | X40: 891 | Y40: =C40&X40 | Z40: =VLOOKUP(Y40,'Data giá Relax hiện tại'!$D:$F,3,0) | AA40: =W40-Z40 | AB40: =AA40/Z40
...

Sheet Cắt Gội（Sao chép2）
A1: SalonID | B1: Mã Salon | C1: GDTM Đề xuất - KB2: Tăng AOV | D1: ID dv | E1: Giá hiện tại | F1: Chênh lệch giá cũ | G1: % Chênh lệch
A2: 2 | B2: 346 KT | C2: 101000 | D2: 891 | E2: 100000 | F2: 1000 | G2: 0.01
A3: 11 | B3: 8 CVL | C3: 100000 | D3: 891 | E3: 100000 | F3: 0 | G3: 0
A4: 12 | B4: 12 LDT | C4: 106000 | D4: 891 | E4: 103000 | F4: 3000 | G4: 0.029126214
A5: 20 | B5: 382 NT | C5: 112000 | D5: 891 | E5: 102000 | F5: 10000 | G5: 0.098039216
A6: 21 | B6: 575 AC | C6: 104000 | D6: 891 | E6: 100000 | F6: 4000 | G6: 0.04
A7: 22 | B7: 927 HG | C7: 100000 | D7: 891 | E7: 100000 | F7: 0 | G7: 0
A8: 39 | B8: 151 CG | C8: 94000 | D8: 891 | E8: 94000 | F8: 0 | G8: 0
A9: 44 | B9: 103 TN | C9: 99000 | D9: 891 | E9: 95000 | F9: 4000 | G9: 0.042105263
A10: 45 | B10: 25 TD | C10: 96000 | D10: 891 | E10: 95000 | F10: 1000 | G10: 0.010526316
A11: 46 | B11: 483 TN | C11: 102000 | D11: 891 | E11: 94000 | F11: 8000 | G11: 0.085106383
A12: 47 | B12: 708 LTT | C12: 110000 | D12: 891 | E12: 103000 | F12: 7000 | G12: 0.067961165
A13: 51 | B13: 420 HTP | C13: 97000 | D13: 891 | E13: 94000 | F13: 3000 | G13: 0.031914894
... A61: 187 | B61: 116 TK | C61: 94000 | D61: 891 | E61: 94000 | F61: 0 | G61: 0

Sheet Cắt Gội（Sao chép）
A1: SalonID | B1: Tên Salon | C1: Mã Salon | D1: GDTM Đề xuất - KB2: Tăng AOV | E1: ID dv | G1: Giá hiện tại | H1: Chênh lệch giá cũ | I1: % Chênh lệch
A2: 2 | B2: 346 Khâm Thiên | C2: 346 KT | D2: 101000 | E2: 891 | F2: 346 KT891 | G2: 100000 | H2: 1000 | I2: 0.01
A3: 11 | B3: 8 Châu Văn Liêm | C3: 8 CVL | D3: 100000 | E3: 891 | F3: 8 CVL891 | G3: 100000 | H3: 0 | I3: 0
A4: 12 | B4: 12 Lê Đức Thọ | C4: 12 LDT | D4: 106000 | E4: 891 | F4: 12 LDT891 | G4: 103000 | H4: 3000 | I4: 0.029126214
A5: 20 | B5: 382 Nguyễn Trãi | C5: 382 NT | D5: 109000 | E5: 891 | F5: 382 NT891 | G5: 102000 | H5: 7000 | I5: 0.068627451
A6: 21 | B6: 575 Âu Cơ | C6: 575 AC | D6: 104000 | E6: 891 | F6: 575 AC891 | G6: 100000 | H6: 4000 | I6: 0.04
A7: 22 | B7: 927 Hậu Giang | C7: 927 HG | D7: 100000 | E7: 891 | F7: 927 HG891 | G7: 100000 | H7: 0 | I7: 0
A8: 39 | B8: 151 Cầu Giấy, Q. CG | C8: 151 CG | D8: 94000 | E8: 891 | F8: 151 CG891 | G8: 94000 | H8: 0 | I8: 0
A9: 44 | B9: 103 Trần Não | C9: 103 TN | D9: 99000 | E9: 891 | F9: 103 TN891 | G9: 95000 | H9: 4000 | I9: 0.042105263
A10: 45 | B10: 25 Tôn Đản | C10: 25 TD | D10: 96000 | E10: 891 | F10: 25 TD891 | G10: 95000 | H10: 1000 | I10: 0.010526316
A11: 46 | B11: 483 Thống Nhất | C11: 483 TN | D11: 102000 | E11: 891 | F11: 483 TN891 | G11: 94000 | H11: 8000 | I11: 0.085106383
A12: 47 | B12: 708 Lê Trọng Tấn | C12: 708 LTT | D12: 110000 | E12: 891 | F12: 708 LTT891 | G12: 103000 | H12: 7000 | I12: 0.067961165
A13: 51 | B13: 420 Huỳnh Tấn Phát | C13: 420 HTP | D13: 97000 | E13: 891 | F13: 420 HTP891 | G13: 94000 | H13: 3000 | I13: 0.031914894
... A57: 302 | B57: 362 Ngô Gia Tự | C57: 362 NGT BN | D57: 94000 | E57: 891 | F57: 362 NGT BN891 | G57: 94000 | H57: 0 | I57: 0

Sheet Uốn
A1: SalonID | B1: Tên Salon | C1: Mã Salon | D1: Tỉnh/TP | E1: Cụm | F1: Loại Cụm | G1: CPI | H1: CPI Level | I1: EPI | J1: EPI Level | K1: Giá Hiện Tại | L1: WTP Sàn (L) | M1: WTP Trần (H) | N1: Hệ Số α_low | O1: Hệ Số α_high | P1: P_min (Khung Dưới) | Q1: P_max (Khung Trên) | R1: Khung Giá Đề Xuất | S1: KB1: Hút Traffic | T1: KB2: Tăng AOV | U1: KB3: Cân Bằng | V1: KB4: Giảm Quá Tải | W1: GDTM Đề xuất - KB3 - Cân Bằng | X1: ID dv | Z1: Giá hiện tại | AA1: Chênh lệch giá cũ | AB1: %
A2: 2 | B2: 346 Khâm Thiên | C2: 346 KT | D2: Hà Nội | E2: 3 | F2: Cụm gốc | G2: 0.6615 | H2: Cao | I2: 0.471 | J2: Cao | K2: 378000 | L2: 251000 | M2: 351000 | N2: 0.35 | O2: 0.55 | P2: 286000 | Q2: 306000 | R2: 286k - 306k | S2: 286000 | T2: 306000 | U2: 296000 | V2: 303000 | W2: =U2 | X2: 1009 | Y2: =C2&X2 | Z2: =VLOOKUP(Y2,'Giá Uốn hiện tại'!$E:$F,2,0) | AA2: =W2-Z2 | AB2: =AA2/Z2
A3: 11 | B3: 8 Châu Văn Liêm | C3: 8 CVL | D3: Hồ Chí Minh | E3: 22 | F3: Cụm mới (cùng tỉnh) | G3: 0.5672 | H3: Trung | I3: 0.3932 | J3: Thấp | K3: 394000 | L3: 202000 | M3: 300000 | N3: 0.25 | O3: 0.5 | P3: 226000 | Q3: 251000 | R3: 226k - 251k | S3: 226000 | T3: 251000 | U3: 239000 | V3: 247000 | W3: =U3 | X3: 1009 | Y3: =C3&X3 | Z3: =VLOOKUP(Y3,'Giá Uốn hiện tại'!$E:$F,2,0) | AA3: =W3-Z3 | AB3: =AA3/Z3
A4: 12 | B4: 12 Lê Đức Thọ | C4: 12 LDT | D4: Hồ Chí Minh | E4: 15 | F4: Cụm gốc | G4: 0.7678 | H4: Cao | I4: 0.4194 | J4: Trung | K4: 424000 | L4: 251000 | M4: 366000 | N4: 0.25 | O4: 0.45 | P4: 280000 | Q4: 303000 | R4: 280k - 303k | S4: 280000 | T4: 303000 | U4: 291000 | V4: 299000 | W4: =U4 | X4: 1009 | Y4: =C4&X4 | Z4: =VLOOKUP(Y4,'Giá Uốn hiện tại'!$E:$F,2,0) | AA4: =W4-Z4 | AB4: =AA4/Z4
A5: 20 | B5: 382 Nguyễn Trãi | C5: 382 NT | D5: Hà Nội | E5: 5 | F5: Cụm gốc | G5: 0.5809 | H5: Trung | I5: 0.5018 | J5: Cao | K5: 394000 | L5: 198000 | M5: 298000 | N5: 0.55 | O5: 0.8 | P5: 253000 | Q5: 278000 | R5: 253k - 278k | S5: 253000 | T5: 278000 | U5: 266000 | V5: 274000 | W5: =U5 | X5: 1009 | Y5: =C5&X5 | Z5: =VLOOKUP(Y5,'Giá Uốn hiện tại'!$E:$F,2,0) | AA5: =W5-Z5 | AB5: =AA5/Z5
A6: 21 | B6: 575 Âu Cơ | C6: 575 AC | D6: Hồ Chí Minh | E6: 18 | F6: Cụm gốc | G6: 0.644 | H6: Cao | I6: 0.4483 | J6: Trung | K6: 378000 | L6: 201000 | M6: 300000 | N6: 0.25 | O6: 0.45 | P6: 226000 | Q6: 246000 | R6: 226k - 246k | S6: 226000 | T6: 246000 | U6: 236000 | V6: 243000 | W6: =U6 | X6: 1009 | Y6: =C6&X6 | Z6: =VLOOKUP(Y6,'Giá Uốn hiện tại'!$E:$F,2,0) | AA6: =W6-Z6 | AB6: =AA6/Z6
A7: 22 | B7: 927 Hậu Giang | C7: 927 HG | D7: Hồ Chí Minh | E7: 22 | F7: Cụm mới (cùng tỉnh) | G7: 0.6209 | H7: Cao | I7: 0.432 | J7: Trung | L7: 202000 | M7: 300000 | N7: 0.25 | O7: 0.45 | P7: 226000 | Q7: 246000 | R7: 226k - 246k | S7: 226000 | T7: 246000 | U7: 236000 | V7: 243000 | W7: =U7 | X7: 1009 | Y7: =C7&X7 | Z7: =VLOOKUP(Y7,'Giá Uốn hiện tại'!$E:$F,2,0) | AA7: =W7-Z7 | AB7: =AA7/Z7
A8: 39 | B8: 151 Cầu Giấy, Q. CG | C8: 151 CG | D8: Hà Nội | E8: 1 | F8: Cụm gốc | G8: 0.6444 | H8: Cao | I8: 0.4063 | J8: Thấp | K8: 378000 | L8: 249000 | M8: 398000 | N8: 0.15 | O8: 0.35 | P8: 271000 | Q8: 301000 | R8: 271k - 301k | S8: 271000 | T8: 301000 | U8: 286000 | V8: 297000 | W8: =U8 | X8: 1009 | Y8: =C8&X8 | Z8: =VLOOKUP(Y8,'Giá Uốn hiện tại'!$E:$F,2,0) | AA8: =W8-Z8 | AB8: =AA8/Z8
A9: 44 | B9: 103 Trần Não | C9: 103 TN | D9: Hồ Chí Minh | E9: 24 | F9: Cụm mới (cùng tỉnh) | G9: 0.5591 | H9: Trung | I9: 0.4948 | J9: Cao | K9: 378000 | L9: 201000 | M9: 349000 | N9: 0.55 | O9: 0.8 | P9: 282000 | Q9: 319000 | R9: 282k - 319k | S9: 282000 | T9: 319000 | U9: 301000 | V9: 314000 | W9: =U9 | X9: 1009 | Y9: =C9&X9 | Z9: =VLOOKUP(Y9,'Giá Uốn hiện tại'!$E:$F,2,0) | AA9: =W9-Z9 | AB9: =AA9/Z9
A10: 45 | B10: 25 Tôn Đản | C10: 25 TD | D10: Hồ Chí Minh | E10: 24 | F10: Cụm mới (cùng tỉnh) | G10: 0.6313 | H10: Cao | I10: 0.4649 | J10: Cao | K10: 394000 | L10: 201000 | M10: 349000 | N10: 0.35 | O10: 0.55 | P10: 253000 | Q10: 282000 | R10: 253k - 282k | S10: 253000 | T10: 282000 | U10: 268000 | V10: 278000 | W10: =U10 | X10: 1009 | Y10: =C10&X10 | Z10: =VLOOKUP(Y10,'Giá Uốn hiện tại'!$E:$F,2,0) | AA10: =W10-Z10 | AB10: =AA10/Z10
A11: 46 | B11: 483 Thống Nhất | C11: 483 TN | D11: Không xác định | E11: 14 | F11: Cụm gốc | G11: 0.5299 | H11: Trung | I11: 0.4186 | J11: Trung | K11: 378000 | L11: 202000 | M11: 300000 | N11: 0.4 | O11: 0.65 | P11: 241000 | Q11: 266000 | R11: 241k - 266k | S11: 241000 | T11: 266000 | U11: 253000 | V11: 262000 | W11: =U11 | X11: 1009 | Y11: =C11&X11 | Z11: =VLOOKUP(Y11,'Giá Uốn hiện tại'!$E:$F,2,0) | AA11: =W11-Z11 | AB11: =AA11/Z11
A12: 47 | B12: 708 Lê Trọng Tấn | C12: 708 LTT | D12: Hồ Chí Minh | E12: 25 | F12: Cụm mới (cùng tỉnh) | G12: 0.5578 | H12: Trung | I12: 0.3585 | J12: Thấp | K12: 424000 | L12: 248000 | M12: 299000 | N12: 0.25 | O12: 0.5 | P12: 261000 | Q12: 274000 | R12: 261k - 274k | S12: 261000 | T12: 274000 | U12: 267000 | V12: 272000 | W12: =U12 | X12: 1009 | Y12: =C12&X12 | Z12: =VLOOKUP(Y12,'Giá Uốn hiện tại'!$E:$F,2,0) | AA12: =W12-Z12 | AB12: =AA12/Z12
A13: 51 | B13: 420 Huỳnh Tấn Phát | C13: 420 HTP | D13: Hồ Chí Minh | E13: 21 | F13: Cụm gốc | G13: 0.5667 | H13: Trung | I13: 0.42 | J13: Trung | K13: 424000 | L13: 204000 | M13: 298000 | N13: 0.4 | O13: 0.65 | P13: 242000 | Q13: 265000 | R13: 242k - 265k | S13: 242000 | T13: 265000 | U13: 253000 | V13: 262000 | W13: =U13 | X13: 1009 | Y13: =C13&X13 | Z13: =VLOOKUP(Y13,'Giá Uốn hiện tại'!$E:$F,2,0) | AA13: =W13-Z13 | AB13: =AA13/Z13
A14: 52 | B14: 451 Phạm Văn Thuận | C14: 451 PVT | D14: Đồng Nai | E14: 12 | F14: Cụm gốc | G14: 0.5405 | H14: Trung | I14: 0.3055 | J14: Thấp | K14: 394000 | L14: 201000 | M14: 299000 | N14: 0.25 | O14: 0.5 | P14: 226000 | Q14: 250000 | R14: 226k - 250k | S14: 226000 | T14: 250000 | U14: 238000 | V14: 246000 | W14: =U14 | X14: 1009 | Y14: =C14&X14 | Z14: =VLOOKUP(Y14,'Giá Uốn hiện tại'!$E:$F,2,0) | AA14: =W14-Z14 | AB14: =AA14/Z14
A15: 58 | B15: 730 Tỉnh lộ 10 | C15: 730 TL10 | D15: Hồ Chí Minh | E15: 22 | F15: Cụm mới (cùng tỉnh) | G15: 0.5145 | H15: Trung | I15: 0.4168 | J15: Trung | K15: 424000 | L15: 202000 | M15: 300000 | N15: 0.4 | O15: 0.65 | P15: 241000 | Q15: 266000 | R15: 241k - 266k | S15: 241000 | T15: 266000 | U15: 253000 | V15: 262000 | W15: =U15 | X15: 1009 | Y15: =C15&X15 | Z15: =VLOOKUP(Y15,'Giá Uốn hiện tại'!$E:$F,2,0) | AA15: =W15-Z15 | AB15: =AA15/Z15
A16: 60 | B16: 80 Phú Lợi | C16: 80 PL BD | D16: Bình Dương | E16: 11 | F16: Cụm gốc | G16: 0.5268 | H16: Trung | I16: 0.366 | J16: Thấp | K16: 424000 | L16: 297000 | M16: 332000 | N16: 0.25 | O16: 0.5 | P16: 306000 | Q16: 314000 | R16: 306k - 314k | S16: 306000 | T16: 314000 | U16: 310000 | V16: 313000 | W16: =U16 | X16: 1009 | Y16: =C16&X16 | Z16: =VLOOKUP(Y16,'Giá Uốn hiện tại'!$E:$F,2,0) | AA16: =W16-Z16 | AB16: =AA16/Z16
A17: 61 | B17: 1180 Quang Trung | C17: 1180 QT | D17: Hồ Chí Minh | E17: 25 | F17: Cụm mới (cùng tỉnh) | G17: 0.6374 | H17: Cao | I17: 0.3781 | J17: Thấp | K17: 394000 | L17: 248000 | M17: 299000 | N17: 0.15 | O17: 0.35 | P17: 256000 | Q17: 266000 | R17: 256k - 266k | S17: 256000 | T17: 266000 | U17: 261000 | V17: 264000 | W17: =U17 | X17: 1009 | Y17: =C17&X17 | Z17: =VLOOKUP(Y17,'Giá Uốn hiện tại'!$E:$F,2,0) | AA17: =W17-Z17 | AB17: =AA17/Z17
A18: 63 | B18: 29 Hiệp Bình | C18: 29 HB | D18: Hồ Chí Minh | E18: 23 | F18: Cụm mới (cùng tỉnh) | G18: 0.5142 | H18: Trung | I18: 0.379 | J18: Thấp | K18: 378000 | L18: 201000 | M18: 299000 | N18: 0.25 | O18: 0.5 | P18: 226000 | Q18: 250000 | R18: 226k - 250k | S18: 226000 | T18: 250000 | U18: 238000 | V18: 246000 | W18: =U18 | X18: 1009 | Y18: =C18&X18 | Z18: =VLOOKUP(Y18,'Giá Uốn hiện tại'!$E:$F,2,0) | AA18: =W18-Z18 | AB18: =AA18/Z18
A19: 65 | B19: 255 Nguyễn An Ninh | C19: 255 NAN | D19: Bình Dương | E19: 27 | F19: Cụm mới (cùng tỉnh) | G19: 0.5626 | H19: Trung | I19: 0.3909 | J19: Thấp | K19: 384000 | L19: 201000 | M19: 299000 | N19: 0.25 | O19: 0.5 | P19: 226000 | Q19: 250000 | R19: 226k - 250k | S19: 226000 | T19: 250000 | U19: 238000 | V19: 246000 | W19: =U19 | X19: 1009 | Y19: =C19&X19 | Z19: =VLOOKUP(Y19,'Giá Uốn hiện tại'!$E:$F,2,0) | AA19: =W19-Z19 | AB19: =AA19/Z19
A20: 69 | B20: 312 Lê Văn Sỹ | C20: 312 LVS | D20: Không xác định | E20: 16 | F20: Cụm gốc | G20: 0.6377 | H20: Cao | I20: 0.4263 | J20: Trung | K20: 424000 | L20: 249000 | M20: 349000 | N20: 0.25 | O20: 0.45 | P20: 274000 | Q20: 294000 | R20: 274k - 294k | S20: 274000 | T20: 294000 | U20: 284000 | V20: 291000 | W20: =U20 | X20: 1009 | Y20: =C20&X20 | Z20: =VLOOKUP(Y20,'Giá Uốn hiện tại'!$E:$F,2,0) | AA20: =W20-Z20 | AB20: =AA20/Z20
A21: 72 | B21: 113 Trần Hưng Đạo | C21: 113 THD AG | D21: An Giang | F21: Độc lập (1 salon trong tỉnh) | G21: 0.4261 | H21: Trung | I21: 0.2966 | J21: Thấp | K21: 424000 | L21: 143000 | M21: 298000 | N21: 0.25 | O21: 0.5 | P21: 182000 | Q21: 220000 | R21: 182k - 220k | S21: 182000 | T21: 220000 | U21: 201000 | V21: 215000 | W21: =U21 | X21: 1009 | Y21: =C21&X21 | Z21: =VLOOKUP(Y21,'Giá Uốn hiện tại'!$E:$F,2,0) | AA21: =W21-Z21 | AB21: =AA21/Z21
A22: 85 | B22: 363 Lương Ngọc Quyến | C22: 363 LNQ TN | D22: Thái Nguyên | F22: Độc lập (1 salon trong tỉnh) | G22: 0.5119 | H22: Trung | I22: 0.3665 | J22: Thấp | K22: 424000 | L22: 200000 | M22: 298000 | N22: 0.25 | O22: 0.5 | P22: 224000 | Q22: 249000 | R22: 224k - 249k | S22: 224000 | T22: 249000 | U22: 237000 | V22: 245000 | W22: =U22 | X22: 1009 | Y22: =C22&X22 | Z22: =VLOOKUP(Y22,'Giá Uốn hiện tại'!$E:$F,2,0) | AA22: =W22-Z22 | AB22: =AA22/Z22
A23: 106 | B23: 76 Phan Văn Hớn | C23: 76 PVH | D23: Hồ Chí Minh | E23: 25 | F23: Cụm mới (cùng tỉnh) | G23: 0.4969 | H23: Trung | I23: 0.37 | J23: Thấp | K23: 394000 | L23: 248000 | M23: 299000 | N23: 0.25 | O23: 0.5 | P23: 261000 | Q23: 274000 | R23: 261k - 274k | S23: 261000 | T23: 274000 | U23: 267000 | V23: 272000 | W23: =U23 | X23: 1009 | Y23: =C23&X23 | Z23: =VLOOKUP(Y23,'Giá Uốn hiện tại'!$E:$F,2,0) | AA23: =W23-Z23 | AB23: =AA23/Z23
A24: 141 | B24: 236 Dương Bá Trạc | C24: 236 DBT | D24: Hồ Chí Minh | E24: 20 | F24: Cụm gốc | G24: 0.6503 | H24: Cao | I24: 0.4151 | J24: Trung | K24: 378000 | L24: 202000 | M24: 299000 | N24: 0.25 | O24: 0.45 | P24: 226000 | Q24: 246000 | R24: 226k - 246k | S24: 226000 | T24: 246000 | U24: 236000 | V24: 243000 | W24: =U24 | X24: 1009 | Y24: =C24&X24 | Z24: =VLOOKUP(Y24,'Giá Uốn hiện tại'!$E:$F,2,0) | AA24: =W24-Z24 | AB24: =AA24/Z24
A25: 143 | B25: 10 Trần Phú | C25: 10 TP | D25: Hà Nội | E25: 7 | F25: Cụm gốc | G25: 0.6802 | H25: Cao | I25: 0.446 | J25: Trung | K25: 424000 | L25: 202000 | M25: 319000 | N25: 0.25 | O25: 0.45 | P25: 231000 | Q25: 255000 | R25: 231k - 255k | S25: 231000 | T25: 255000 | U25: 243000 | V25: 251000 | W25: =U25 | X25: 1009 | Y25: =C25&X25 | Z25: =VLOOKUP(Y25,'Giá Uốn hiện tại'!$E:$F,2,0) | AA25: =W25-Z25 | AB25: =AA25/Z25
A26: 144 | B26: 168 Nguyễn Văn Cừ | C26: 168 NVC | D26: Hà Nội | E26: 29 | F26: Cụm mới (cùng tỉnh) | G26: 0.5388 | H26: Trung | I26: 0.4732 | J26: Cao | K26: 379000 | L26: 297000 | M26: 401000 | N26: 0.55 | O26: 0.8 | P26: 354000 | Q26: 380000 | R26: 354k - 380k | S26: 354000 | T26: 380000 | U26: 367000 | V26: 376000 | W26: =U26 | X26: 1009 | Y26: =C26&X26 | Z26: =VLOOKUP(Y26,'Giá Uốn hiện tại'!$E:$F,2,0) | AA26: =W26-Z26 | AB26: =AA26/Z26
A27: 145 | B27: 237 Nguyễn Thị Thập | C27: 237 NTT | D27: Hồ Chí Minh | E27: 21 | F27: Cụm gốc | G27: 0.7782 | H27: Cao | I27: 0.4394 | J27: Trung | K27: 424000 | L27: 204000 | M27: 298000 | N27: 0.25 | O27: 0.45 | P27: 228000 | Q27: 246000 | R27: 228k - 246k | S27: 228000 | T27: 246000 | U27: 237000 | V27: 243000 | W27: =U27 | X27: 1009 | Y27: =C27&X27 | Z27: =VLOOKUP(Y27,'Giá Uốn hiện tại'!$E:$F,2,0) | AA27: =W27-Z27 | AB27: =AA27/Z27
A28: 146 | B28: 109 Trần Quốc Hoàn | C28: 109 TQH | D28: Hà Nội | E28: 1 | F28: Cụm gốc | G28: 0.6773 | H28: Cao | I28: 0.4359 | J28: Trung | K28: 378000 | L28: 249000 | M28: 398000 | N28: 0.25 | O28: 0.45 | P28: 286000 | Q28: 316000 | R28: 286k - 316k | S28: 286000 | T28: 316000 | U28: 301000 | V28: 312000 | W28: =U28 | X28: 1009 | Y28: =C28&X28 | Z28: =VLOOKUP(Y28,'Giá Uốn hiện tại'!$E:$F,2,0) | AA28: =W28-Z28 | AB28: =AA28/Z28
A29: 147 | B29: 99 Tân Sơn Nhì | C29: 99 TSN | D29: Hồ Chí Minh | E29: 18 | F29: Cụm gốc | G29: 0.6664 | H29: Cao | I29: 0.4415 | J29: Trung | K29: 424000 | L29: 201000 | M29: 300000 | N29: 0.25 | O29: 0.45 | P29: 226000 | Q29: 246000 | R29: 226k - 246k | S29: 226000 | T29: 246000 | U29: 236000 | V29: 243000 | W29: =U29 | X29: 1009 | Y29: =C29&X29 | Z29: =VLOOKUP(Y29,'Giá Uốn hiện tại'!$E:$F,2,0) | AA29: =W29-Z29 | AB29: =AA29/Z29
A30: 182 | B30: 186 Đinh Tiên Hoàng | C30: 186 DTH | D30: Hồ Chí Minh | E30: 24 | F30: Cụm mới (cùng tỉnh) | G30: 0.6312 | H30: Cao | I30: 0.4414 | J30: Trung | K30: 424000 | L30: 201000 | M30: 349000 | N30: 0.25 | O30: 0.45 | P30: 238000 | Q30: 268000 | R30: 238k - 268k | S30: 238000 | T30: 268000 | U30: 253000 | V30: 263000 | W30: =U30 | X30: 1009 | Y30: =C30&X30 | Z30: =VLOOKUP(Y30,'Giá Uốn hiện tại'!$E:$F,2,0) | AA30: =W30-Z30 | AB30: =AA30/Z30
A31: 184 | B31: 36 đường N1, KCN Mỹ Phước 1 | C31: 36 N1 BD | D31: Bình Dương | E31: 27 | F31: Cụm mới (cùng tỉnh) | G31: 0.553 | H31: Trung | I31: 0.3126 | J31: Thấp | K31: 424000 | L31: 201000 | M31: 299000 | N31: 0.25 | O31: 0.5 | P31: 226000 | Q31: 250000 | R31: 226k - 250k | S31: 226000 | T31: 250000 | U31: 238000 | V31: 246000 | W31: =U31 | X31: 1009 | Y31: =C31&X31 | Z31: =VLOOKUP(Y31,'Giá Uốn hiện tại'!$E:$F,2,0) | AA31: =W31-Z31 | AB31: =AA31/Z31
A32: 188 | B32: 190 Hòa Bình | C32: 190 HB | D32: Hồ Chí Minh | E32: 22 | F32: Cụm mới (cùng tỉnh) | G32: 0.6785 | H32: Cao | I32: 0.412 | J32: Thấp | K32: 378000 | L32: 202000 | M32: 300000 | N32: 0.15 | O32: 0.35 | P32: 217000 | Q32: 236000 | R32: 217k - 236k | S32: 217000 | T32: 236000 | U32: 226000 | V32: 233000 | W32: =U32 | X32: 1009 | Y32: =C32&X32 | Z32: =VLOOKUP(Y32,'Giá Uốn hiện tại'!$E:$F,2,0) | AA32: =W32-Z32 | AB32: =AA32/Z32
A33: 192 | B33: 264 Lạc Long Quân | C33: 264 LLQ | D33: Hà Nội | E33: 29 | F33: Cụm mới (cùng tỉnh) | G33: 0.5709 | H33: Trung | I33: 0.4294 | J33: Trung | K33: 394000 | L33: 297000 | M33: 401000 | N33: 0.4 | O33: 0.65 | P33: 339000 | Q33: 365000 | R33: 339k - 365k | S33: 339000 | T33: 365000 | U33: 352000 | V33: 361000 | W33: =U33 | X33: 1009 | Y33: =C33&X33 | Z33: =VLOOKUP(Y33,'Giá Uốn hiện tại'!$E:$F,2,0) | AA33: =W33-Z33 | AB33: =AA33/Z33
A34: 193 | B34: 145 Tô Hiến Thành | C34: 145 THT | D34: Hồ Chí Minh | E34: 19 | F34: Cụm gốc | G34: 0.5476 | H34: Trung | I34: 0.4086 | J34: Thấp | K34: 424000 | L34: 200000 | M34: 298000 | N34: 0.25 | O34: 0.5 | P34: 224000 | Q34: 249000 | R34: 224k - 249k | S34: 224000 | T34: 249000 | U34: 237000 | V34: 245000 | W34: =U34 | X34: 1009 | Y34: =C34&X34 | Z34: =VLOOKUP(Y34,'Giá Uốn hiện tại'!$E:$F,2,0) | AA34: =W34-Z34 | AB34: =AA34/Z34
... A37: 197 | B37: 65 Cầu Diễn | C37: 65 CD | D37: Hà Nội | E37: 30 | F37: Cụm mới (cùng tỉnh) | G37: 0.5089 | H37: Trung | I37: 0.3908 | J37: Thấp | K37: 424000 | L37: 202000 | M37: 299000 | N37: 0.25 | O37: 0.5 | P37: 226000 | Q37: 250000 | R37: 226k - 250k | S37: 226000 | T37: 250000 | U37: 238000 | V37: 247000 | W37: =U37 | X37: 1009 | Y37: =C37&X37 | Z37: =VLOOKUP(Y37,'Giá Uốn hiện tại'!$E:$F,2,0) | AA37: =W37-Z37 | AB37: =AA37/Z37
A38: 199 | B38: 7 Đỗ Tường Phong | C38: 7 DTP LA | D38: Long An | F38: Độc lập (1 salon trong tỉnh) | G38: 0.5319 | H38: Trung | I38: 0.3842 | J38: Thấp | K38: 424000 | L38: 200000 | M38: 251000 | N38: 0.25 | O38: 0.5 | P38: 213000 | Q38: 226000 | R38: 213k - 226k | S38: 213000 | T38: 226000 | U38: 219000 | V38: 224000 | W38: =U38 | X38: 1009 | Y38: =C38&X38 | Z38: =VLOOKUP(Y38,'Giá Uốn hiện tại'!$E:$F,2,0) | AA38: =W38-Z38 | AB38: =AA38/Z38
A39: 204 | B39: 401/1 Nguyễn Duy Trinh | C39: 401/1 NDT | D39: Hồ Chí Minh | E39: 23 | F39: Cụm mới (cùng tỉnh) | G39: 0.5599 | H39: Trung | I39: 0.3979 | J39: Thấp | K39: 378000 | L39: 201000 | M39: 299000 | N39: 0.25 | O39: 0.5 | P39: 226000 | Q39: 250000 | R39: 226k - 250k | S39: 226000 | T39: 250000 | U39: 238000 | V39: 246000 | W39: =U39 | X39: 1009 | Y39: =C39&X39 | Z39: =VLOOKUP(Y39,'Giá Uốn hiện tại'!$E:$F,2,0) | AA39: =W39-Z39 | AB39: =AA39/Z39
A40: 205 | B40: 341 Xô Viết Nghệ Tĩnh | C40: 341 XVNT | D40: Hồ Chí Minh | E40: 17 | F40: Cụm gốc | G40: 0.6578 | H40: Cao | I40: 0.3726 | J40: Thấp | K40: 378000 | L40: 202000 | M40: 350000 | N40: 0.15 | O40: 0.35 | P40: 224000 | Q40: 254000 | R40: 224k - 254k | S40: 224000 | T40: 254000 | U40: 239000 | V40: 249000 | W40: =U40 | X40: 1009 | Y40: =C40&X40 | Z40: =VLOOKUP(Y40,'Giá Uốn hiện tại'!$E:$F,2,0) | AA40: =W40-Z40 | AB40: =AA40/Z40
A41: 210 | B41: 148B Trương Định | C41: 148 TD | D41: Hà Nội | E41: 6 | F41: Cụm gốc | G41: 0.6448 | H41: Cao | I41: 0.361 | J41: Thấp | K41: 424000 | L41: 289000 | M41: 353000 | N41: 0.15 | O41: 0.35 | P41: 299000 | Q41: 311000 | R41: 299k - 311k | S41: 299000 | T41: 311000 | U41: 305000 | V41: 309000 | W41: =U41 | X41: 1009 | Y41: =C41&X41 | Z41: =VLOOKUP(Y41,'Giá Uốn hiện tại'!$E:$F,2,0) | AA41: =W41-Z41 | AB41: =AA41/Z41
A42: 212 | B42: 58 Nguyễn Văn Cừ | C42: 58 NVC NA | D42: Nghệ An | E42: 10 | F42: Cụm gốc | G42: 0.5736 | H42: Trung | I42: 0.3468 | J42: Thấp | K42: 394000 | L42: 298000 | M42: 353000 | N42: 0.25 | O42: 0.5 | P42: 312000 | Q42: 326000 | R42: 312k - 326k | S42: 312000 | T42: 326000 | U42: 319000 | V42: 323000 | W42: =U42 | X42: 1009 | Y42: =C42&X42 | Z42: =VLOOKUP(Y42,'Giá Uốn hiện tại'!$E:$F,2,0) | AA42: =W42-Z42 | AB42: =AA42/Z42
...

Sheet Uốn（Sao chép）
A1: SalonID | B1: Tên Salon | C1: Mã Salon | D1: Giá mới | E1: ID dv | F1: Tên dịch vụ | H1: Giá hiện tại | I1: Chênh lệch giá cũ | J1: %
A2: 2 | B2: 346 Khâm Thiên | C2: 346 KT | D2: 296000 | E2: 1009 | F2: (NEW) Uốn/Duỗi/Định hình full đầu tạo form vào nếp tự nhiên | G2: 346 KT1009 | H2: 416000 | I2: -120000 | J2: -0.28846154
A3: 11 | B3: 8 Châu Văn Liêm | C3: 8 CVL | D3: 239000 | E3: 1009 | F3: (NEW) Uốn/Duỗi/Định hình full đầu tạo form vào nếp tự nhiên | G3: 8 CVL1009 | H3: 396000 | I3: -157000 | J3: -0.39646465
A4: 12 | B4: 12 Lê Đức Thọ | C4: 12 LDT | D4: 291000 | E4: 1009 | F4: (NEW) Uốn/Duỗi/Định hình full đầu tạo form vào nếp tự nhiên | G4: 12 LDT1009 | H4: 396000 | I4: -105000 | J4: -0.26515152
A5: 20 | B5: 382 Nguyễn Trãi | C5: 382 NT | D5: 266000 | E5: 1009 | F5: (NEW) Uốn/Duỗi/Định hình full đầu tạo form vào nếp tự nhiên | G5: 382 NT1009 | H5: 396000 | I5: -130000 | J5: -0.32828283
A6: 21 | B6: 575 Âu Cơ | C6: 575 AC | D6: 236000 | E6: 1009 | F6: (NEW) Uốn/Duỗi/Định hình full đầu tạo form vào nếp tự nhiên | G6: 575 AC1009 | H6: 396000 | I6: -160000 | J6: -0.4040404
A7: 22 | B7: 927 Hậu Giang | C7: 927 HG | D7: 236000 | E7: 1009 | F7: (NEW) Uốn/Duỗi/Định hình full đầu tạo form vào nếp tự nhiên | G7: 927 HG1009 | H7: 396000 | I7: -160000 | J7: -0.4040404
A8: 39 | B8: 151 Cầu Giấy, Q. CG | C8: 151 CG | D8: 286000 | E8: 1009 | F8: (NEW) Uốn/Duỗi/Định hình full đầu tạo form vào nếp tự nhiên | G8: 151 CG1009 | H8: 396000 | I8: -110000 | J8: -0.27777778
A9: 44 | B9: 103 Trần Não | C9: 103 TN | D9: 301000 | E9: 1009 | F9: (NEW) Uốn/Duỗi/Định hình full đầu tạo form vào nếp tự nhiên | G9: 103 TN1009 | H9: 406000 | I9: -105000 | J9: -0.25862069
A10: 45 | B10: 25 Tôn Đản | C10: 25 TD | D10: 268000 | E10: 1009 | F10: (NEW) Uốn/Duỗi/Định hình full đầu tạo form vào nếp tự nhiên | G10: 25 TD1009 | H10: 416000 | I10: -148000 | J10: -0.35576923
A11: 46 | B11: 483 Thống Nhất | C11: 483 TN | D11: 253000 | E11: 1009 | F11: (NEW) Uốn/Duỗi/Định hình full đầu tạo form vào nếp tự nhiên | G11: 483 TN1009 | H11: 396000 | I11: -143000 | J11: -0.36111111
A12: 47 | B12: 708 Lê Trọng Tấn | C12: 708 LTT | D12: 267000 | E12: 1009 | F12: (NEW) Uốn/Duỗi/Định hình full đầu tạo form vào nếp tự nhiên | G12: 708 LTT1009 | H12: 396000 | I12: -129000 | J12: -0.32575758
A13: 51 | B13: 420 Huỳnh Tấn Phát | C13: 420 HTP | D13: 253000 | E13: 1009 | F13: (NEW) Uốn/Duỗi/Định hình full đầu tạo form vào nếp tự nhiên | G13: 420 HTP1009 | H13: 396000 | I13: -143000 | J13: -0.36111111
... A56: 302 | B56: 362 Ngô Gia Tự | C56: 362 NGT BN | D56: 289000 | E56: 1009 | F56: (NEW) Uốn/Duỗi/Định hình full đầu tạo form vào nếp tự nhiên | G56: 362 NGT BN1009 | H56: 396000 | I56: -107000 | J56: -0.27020202

Sheet Nhuộm
A1: SalonID | B1: Tên Salon | C1: Mã Salon | D1: Tỉnh/TP | E1: Cụm | F1: Loại Cụm | G1: CPI | H1: CPI Level | I1: EPI | J1: EPI Level | K1: Giá Hiện Tại | L1: WTP Sàn (L) | M1: WTP Trần (H) | N1: Hệ Số α_low | O1: Hệ Số α_high | P1: P_min (Khung Dưới) | Q1: P_max (Khung Trên) | R1: Khung Giá Đề Xuất | S1: KB1: Hút Traffic | T1: KB2: Tăng AOV | U1: KB3: Cân Bằng | V1: KB4: Giảm Quá Tải | W1: GDTM đề xuất = KB1: Hút Traffic | X1: ID dv | Z1: Giá hiện tại | AA1: Chênh lệch giá cũ | AB1: %
A2: 2 | B2: 346 Khâm Thiên | C2: 346 KT | D2: Hà Nội | E2: 3 | F2: Cụm gốc | G2: 0.6615 | H2: Cao | I2: 0.471 | J2: Cao | K2: 218000 | L2: 205000 | M2: 349000 | N2: 0.35 | O2: 0.55 | P2: 255000 | Q2: 284000 | R2: 255k - 284k | S2: 255000 | T2: 284000 | U2: 270000 | V2: 280000 | W2: =S2 | X2: 960 | Y2: =C2&X2 | Z2: =VLOOKUP(Y2,'Giá Uốn hiện tại'!$E:$F,2,0) | AA2: =W2-Z2 | AB2: =AA2/Z2
A3: 11 | B3: 8 Châu Văn Liêm | C3: 8 CVL | D3: Hồ Chí Minh | E3: 22 | F3: Cụm mới (cùng tỉnh) | G3: 0.5672 | H3: Trung | I3: 0.3932 | J3: Thấp | K3: 229000 | L3: 201000 | M3: 299000 | N3: 0.25 | O3: 0.5 | P3: 226000 | Q3: 250000 | R3: 226k - 250k | S3: 226000 | T3: 250000 | U3: 238000 | V3: 246000 | W3: =S3 | X3: 960 | Y3: =C3&X3 | Z3: =VLOOKUP(Y3,'Giá Uốn hiện tại'!$E:$F,2,0) | AA3: =W3-Z3 | AB3: =AA3/Z3
A4: 12 | B4: 12 Lê Đức Thọ | C4: 12 LDT | D4: Hồ Chí Minh | E4: 15 | F4: Cụm gốc | G4: 0.7678 | H4: Cao | I4: 0.4194 | J4: Trung | K4: 218000 | L4: 203000 | M4: 300000 | N4: 0.25 | O4: 0.45 | P4: 227000 | Q4: 247000 | R4: 227k - 247k | S4: 227000 | T4: 247000 | U4: 237000 | V4: 244000 | W4: =S4 | X4: 960 | Y4: =C4&X4 | Z4: =VLOOKUP(Y4,'Giá Uốn hiện tại'!$E:$F,2,0) | AA4: =W4-Z4 | AB4: =AA4/Z4
A5: 20 | B5: 382 Nguyễn Trãi | C5: 382 NT | D5: Hà Nội | E5: 5 | F5: Cụm gốc | G5: 0.5809 | H5: Trung | I5: 0.5018 | J5: Cao | K5: 229000 | L5: 202000 | M5: 328000 | N5: 0.55 | O5: 0.8 | P5: 271000 | Q5: 303000 | R5: 271k - 303k | S5: 271000 | T5: 303000 | U5: 287000 | V5: 298000 | W5: =S5 | X5: 960 | Y5: =C5&X5 | Z5: =VLOOKUP(Y5,'Giá Uốn hiện tại'!$E:$F,2,0) | AA5: =W5-Z5 | AB5: =AA5/Z5
A6: 21 | B6: 575 Âu Cơ | C6: 575 AC | D6: Hồ Chí Minh | E6: 18 | F6: Cụm gốc | G6: 0.644 | H6: Cao | I6: 0.4483 | J6: Trung | K6: 218000 | L6: 200000 | M6: 299000 | N6: 0.25 | O6: 0.45 | P6: 225000 | Q6: 245000 | R6: 225k - 245k | S6: 225000 | T6: 245000 | U6: 235000 | V6: 242000 | W6: =S6 | X6: 960 | Y6: =C6&X6 | Z6: =VLOOKUP(Y6,'Giá Uốn hiện tại'!$E:$F,2,0) | AA6: =W6-Z6 | AB6: =AA6/Z6
A7: 22 | B7: 927 Hậu Giang | C7: 927 HG | D7: Hồ Chí Minh | E7: 22 | F7: Cụm mới (cùng tỉnh) | G7: 0.6209 | H7: Cao | I7: 0.432 | J7: Trung | L7: 201000 | M7: 299000 | N7: 0.25 | O7: 0.45 | P7: 226000 | Q7: 245000 | R7: 226k - 245k | S7: 226000 | T7: 245000 | U7: 235000 | V7: 242000 | W7: =S7 | X7: 960 | Y7: =C7&X7 | Z7: =VLOOKUP(Y7,'Giá Uốn hiện tại'!$E:$F,2,0) | AA7: =W7-Z7 | AB7: =AA7/Z7
A8: 39 | B8: 151 Cầu Giấy, Q. CG | C8: 151 CG | D8: Hà Nội | E8: 1 | F8: Cụm gốc | G8: 0.6444 | H8: Cao | I8: 0.4063 | J8: Thấp | K8: 218000 | L8: 250000 | M8: 346000 | N8: 0.15 | O8: 0.35 | P8: 264000 | Q8: 284000 | R8: 264k - 284k | S8: 264000 | T8: 284000 | U8: 274000 | V8: 281000 | W8: =S8 | X8: 960 | Y8: =C8&X8 | Z8: =VLOOKUP(Y8,'Giá Uốn hiện tại'!$E:$F,2,0) | AA8: =W8-Z8 | AB8: =AA8/Z8
A9: 44 | B9: 103 Trần Não | C9: 103 TN | D9: Hồ Chí Minh | E9: 24 | F9: Cụm mới (cùng tỉnh) | G9: 0.5591 | H9: Trung | I9: 0.4948 | J9: Cao | K9: 218000 | L9: 203000 | M9: 299000 | N9: 0.55 | O9: 0.8 | P9: 256000 | Q9: 280000 | R9: 256k - 280k | S9: 256000 | T9: 280000 | U9: 268000 | V9: 276000 | W9: =S9 | X9: 960 | Y9: =C9&X9 | Z9: =VLOOKUP(Y9,'Giá Uốn hiện tại'!$E:$F,2,0) | AA9: =W9-Z9 | AB9: =AA9/Z9
A10: 45 | B10: 25 Tôn Đản | C10: 25 TD | D10: Hồ Chí Minh | E10: 24 | F10: Cụm mới (cùng tỉnh) | G10: 0.6313 | H10: Cao | I10: 0.4649 | J10: Cao | K10: 218000 | L10: 203000 | M10: 299000 | N10: 0.35 | O10: 0.55 | P10: 237000 | Q10: 256000 | R10: 237k - 256k | S10: 237000 | T10: 256000 | U10: 246000 | V10: 253000 | W10: =S10 | X10: 960 | Y10: =C10&X10 | Z10: =VLOOKUP(Y10,'Giá Uốn hiện tại'!$E:$F,2,0) | AA10: =W10-Z10 | AB10: =AA10/Z10
A11: 46 | B11: 483 Thống Nhất | C11: 483 TN | D11: Không xác định | E11: 14 | F11: Cụm gốc | G11: 0.5299 | H11: Trung | I11: 0.4186 | J11: Trung | K11: 218000 | L11: 204000 | M11: 301000 | N11: 0.4 | O11: 0.65 | P11: 243000 | Q11: 267000 | R11: 243k - 267k | S11: 243000 | T11: 267000 | U11: 255000 | V11: 263000 | W11: =S11 | X11: 960 | Y11: =C11&X11 | Z11: =VLOOKUP(Y11,'Giá Uốn hiện tại'!$E:$F,2,0) | AA11: =W11-Z11 | AB11: =AA11/Z11
A12: 47 | B12: 708 Lê Trọng Tấn | C12: 708 LTT | D12: Hồ Chí Minh | E12: 25 | F12: Cụm mới (cùng tỉnh) | G12: 0.5578 | H12: Trung | I12: 0.3585 | J12: Thấp | K12: 218000 | L12: 204000 | M12: 302000 | N12: 0.25 | O12: 0.5 | P12: 228000 | Q12: 253000 | R12: 228k - 253k | S12: 228000 | T12: 253000 | U12: 241000 | V12: 249000 | W12: =S12 | X12: 960 | Y12: =C12&X12 | Z12: =VLOOKUP(Y12,'Giá Uốn hiện tại'!$E:$F,2,0) | AA12: =W12-Z12 | AB12: =AA12/Z12
A13: 51 | B13: 420 Huỳnh Tấn Phát | C13: 420 HTP | D13: Hồ Chí Minh | E13: 21 | F13: Cụm gốc | G13: 0.5667 | H13: Trung | I13: 0.42 | J13: Trung | K13: 218000 | L13: 203000 | M13: 299000 | N13: 0.4 | O13: 0.65 | P13: 241000 | Q13: 265000 | R13: 241k - 265k | S13: 241000 | T13: 265000 | U13: 253000 | V13: 262000 | W13: =S13 | X13: 960 | Y13: =C13&X13 | Z13: =VLOOKUP(Y13,'Giá Uốn hiện tại'!$E:$F,2,0) | AA13: =W13-Z13 | AB13: =AA13/Z13
A14: 52 | B14: 451 Phạm Văn Thuận | C14: 451 PVT | D14: Đồng Nai | E14: 12 | F14: Cụm gốc | G14: 0.5405 | H14: Trung | I14: 0.3055 | J14: Thấp | K14: 218000 | L14: 181000 | M14: 297000 | N14: 0.25 | O14: 0.5 | P14: 210000 | Q14: 239000 | R14: 210k - 239k | S14: 210000 | T14: 239000 | U14: 224000 | V14: 235000 | W14: =S14 | X14: 960 | Y14: =C14&X14 | Z14: =VLOOKUP(Y14,'Giá Uốn hiện tại'!$E:$F,2,0) | AA14: =W14-Z14 | AB14: =AA14/Z14
A15: 58 | B15: 730 Tỉnh lộ 10 | C15: 730 TL10 | D15: Hồ Chí Minh | E15: 22 | F15: Cụm mới (cùng tỉnh) | G15: 0.5145 | H15: Trung | I15: 0.4168 | J15: Trung | K15: 218000 | L15: 201000 | M15: 299000 | N15: 0.4 | O15: 0.65 | P15: 240000 | Q15: 265000 | R15: 240k - 265k | S15: 240000 | T15: 265000 | U15: 252000 | V15: 261000 | W15: =S15 | X15: 960 | Y15: =C15&X15 | Z15: =VLOOKUP(Y15,'Giá Uốn hiện tại'!$E:$F,2,0) | AA15: =W15-Z15 | AB15: =AA15/Z15
A16: 60 | B16: 80 Phú Lợi | C16: 80 PL BD | D16: Bình Dương | E16: 11 | F16: Cụm gốc | G16: 0.5268 | H16: Trung | I16: 0.366 | J16: Thấp | K16: 218000 | L16: 249000 | M16: 351000 | N16: 0.25 | O16: 0.5 | P16: 274000 | Q16: 300000 | R16: 274k - 300k | S16: 274000 | T16: 300000 | U16: 287000 | V16: 296000 | W16: =S16 | X16: 960 | Y16: =C16&X16 | Z16: =VLOOKUP(Y16,'Giá Uốn hiện tại'!$E:$F,2,0) | AA16: =W16-Z16 | AB16: =AA16/Z16
A17: 61 | B17: 1180 Quang Trung | C17: 1180 QT | D17: Hồ Chí Minh | E17: 25 | F17: Cụm mới (cùng tỉnh) | G17: 0.6374 | H17: Cao | I17: 0.3781 | J17: Thấp | K17: 229000 | L17: 204000 | M17: 302000 | N17: 0.15 | O17: 0.35 | P17: 219000 | Q17: 238000 | R17: 219k - 238k | S17: 219000 | T17: 238000 | U17: 228000 | V17: 235000 | W17: =S17 | X17: 960 | Y17: =C17&X17 | Z17: =VLOOKUP(Y17,'Giá Uốn hiện tại'!$E:$F,2,0) | AA17: =W17-Z17 | AB17: =AA17/Z17
A18: 63 | B18: 29 Hiệp Bình | C18: 29 HB | D18: Hồ Chí Minh | E18: 23 | F18: Cụm mới (cùng tỉnh) | G18: 0.5142 | H18: Trung | I18: 0.379 | J18: Thấp | K18: 218000 | L18: 203000 | M18: 300000 | N18: 0.25 | O18: 0.5 | P18: 227000 | Q18: 252000 | R18: 227k - 252k | S18: 227000 | T18: 252000 | U18: 239000 | V18: 248000 | W18: =S18 | X18: 960 | Y18: =C18&X18 | Z18: =VLOOKUP(Y18,'Giá Uốn hiện tại'!$E:$F,2,0) | AA18: =W18-Z18 | AB18: =AA18/Z18
A19: 65 | B19: 255 Nguyễn An Ninh | C19: 255 NAN | D19: Bình Dương | E19: 27 | F19: Cụm mới (cùng tỉnh) | G19: 0.5626 | H19: Trung | I19: 0.3909 | J19: Thấp | K19: 218000 | L19: 299000 | M19: 348000 | N19: 0.25 | O19: 0.5 | P19: 311000 | Q19: 324000 | R19: 311k - 324k | S19: 311000 | T19: 324000 | U19: 317000 | V19: 322000 | W19: =S19 | X19: 960 | Y19: =C19&X19 | Z19: =VLOOKUP(Y19,'Giá Uốn hiện tại'!$E:$F,2,0) | AA19: =W19-Z19 | AB19: =AA19/Z19
A20: 69 | B20: 312 Lê Văn Sỹ | C20: 312 LVS | D20: Không xác định | E20: 16 | F20: Cụm gốc | G20: 0.6377 | H20: Cao | I20: 0.4263 | J20: Trung | K20: 218000 | L20: 198000 | M20: 298000 | N20: 0.25 | O20: 0.45 | P20: 223000 | Q20: 243000 | R20: 223k - 243k | S20: 223000 | T20: 243000 | U20: 233000 | V20: 240000 | W20: =S20 | X20: 960 | Y20: =C20&X20 | Z20: =VLOOKUP(Y20,'Giá Uốn hiện tại'!$E:$F,2,0) | AA20: =W20-Z20 | AB20: =AA20/Z20
A21: 72 | B21: 113 Trần Hưng Đạo | C21: 113 THD AG | D21: An Giang | F21: Độc lập (1 salon trong tỉnh) | G21: 0.4261 | H21: Trung | I21: 0.2966 | J21: Thấp | K21: 218000 | L21: 201000 | M21: 251000 | N21: 0.25 | O21: 0.5 | P21: 214000 | Q21: 226000 | R21: 214k - 226k | S21: 214000 | T21: 226000 | U21: 220000 | V21: 224000 | W21: =S21 | X21: 960 | Y21: =C21&X21 | Z21: =VLOOKUP(Y21,'Giá Uốn hiện tại'!$E:$F,2,0) | AA21: =W21-Z21 | AB21: =AA21/Z21
A22: 85 | B22: 363 Lương Ngọc Quyến | C22: 363 LNQ TN | D22: Thái Nguyên | F22: Độc lập (1 salon trong tỉnh) | G22: 0.5119 | H22: Trung | I22: 0.3665 | J22: Thấp | K22: 218000 | L22: 297000 | M22: 497000 | N22: 0.25 | O22: 0.5 | P22: 347000 | Q22: 397000 | R22: 347k - 397k | S22: 347000 | T22: 397000 | U22: 372000 | V22: 390000 | W22: =S22 | X22: 960 | Y22: =C22&X22 | Z22: =VLOOKUP(Y22,'Giá Uốn hiện tại'!$E:$F,2,0) | AA22: =W22-Z22 | AB22: =AA22/Z22
A23: 106 | B23: 76 Phan Văn Hớn | C23: 76 PVH | D23: Hồ Chí Minh | E23: 25 | F23: Cụm mới (cùng tỉnh) | G23: 0.4969 | H23: Trung | I23: 0.37 | J23: Thấp | K23: 218000 | L23: 204000 | M23: 302000 | N23: 0.25 | O23: 0.5 | P23: 228000 | Q23: 253000 | R23: 228k - 253k | S23: 228000 | T23: 253000 | U23: 241000 | V23: 249000 | W23: =S23 | X23: 960 | Y23: =C23&X23 | Z23: =VLOOKUP(Y23,'Giá Uốn hiện tại'!$E:$F,2,0) | AA23: =W23-Z23 | AB23: =AA23/Z23
A24: 141 | B24: 236 Dương Bá Trạc | C24: 236 DBT | D24: Hồ Chí Minh | E24: 20 | F24: Cụm gốc | G24: 0.6503 | H24: Cao | I24: 0.4151 | J24: Trung | K24: 218000 | L24: 203000 | M24: 301000 | N24: 0.25 | O24: 0.45 | P24: 228000 | Q24: 247000 | R24: 228k - 247k | S24: 228000 | T24: 247000 | U24: 237000 | V24: 244000 | W24: =S24 | X24: 960 | Y24: =C24&X24 | Z24: =VLOOKUP(Y24,'Giá Uốn hiện tại'!$E:$F,2,0) | AA24: =W24-Z24 | AB24: =AA24/Z24
A25: 143 | B25: 10 Trần Phú | C25: 10 TP | D25: Hà Nội | E25: 7 | F25: Cụm gốc | G25: 0.6802 | H25: Cao | I25: 0.446 | J25: Trung | K25: 218000 | L25: 201000 | M25: 298000 | N25: 0.25 | O25: 0.45 | P25: 225000 | Q25: 245000 | R25: 225k - 245k | S25: 225000 | T25: 245000 | U25: 235000 | V25: 242000 | W25: =S25 | X25: 960 | Y25: =C25&X25 | Z25: =VLOOKUP(Y25,'Giá Uốn hiện tại'!$E:$F,2,0) | AA25: =W25-Z25 | AB25: =AA25/Z25
A26: 144 | B26: 168 Nguyễn Văn Cừ | C26: 168 NVC | D26: Hà Nội | E26: 29 | F26: Cụm mới (cùng tỉnh) | G26: 0.5388 | H26: Trung | I26: 0.4732 | J26: Cao | K26: 229000 | L26: 204000 | M26: 401000 | N26: 0.55 | O26: 0.8 | P26: 312000 | Q26: 362000 | R26: 312k - 362k | S26: 312000 | T26: 362000 | U26: 337000 | V26: 354000 | W26: =S26 | X26: 960 | Y26: =C26&X26 | Z26: =VLOOKUP(Y26,'Giá Uốn hiện tại'!$E:$F,2,0) | AA26: =W26-Z26 | AB26: =AA26/Z26
A27: 145 | B27: 237 Nguyễn Thị Thập | C27: 237 NTT | D27: Hồ Chí Minh | E27: 21 | F27: Cụm gốc | G27: 0.7782 | H27: Cao | I27: 0.4394 | J27: Trung | K27: 214000 | L27: 203000 | M27: 299000 | N27: 0.25 | O27: 0.45 | P27: 227000 | Q27: 246000 | R27: 227k - 246k | S27: 227000 | T27: 246000 | U27: 237000 | V27: 243000 | W27: =S27 | X27: 960 | Y27: =C27&X27 | Z27: =VLOOKUP(Y27,'Giá Uốn hiện tại'!$E:$F,2,0) | AA27: =W27-Z27 | AB27: =AA27/Z27
A28: 146 | B28: 109 Trần Quốc Hoàn | C28: 109 TQH | D28: Hà Nội | E28: 1 | F28: Cụm gốc | G28: 0.6773 | H28: Cao | I28: 0.4359 | J28: Trung | K28: 218000 | L28: 250000 | M28: 346000 | N28: 0.25 | O28: 0.45 | P28: 274000 | Q28: 293000 | R28: 274k - 293k | S28: 274000 | T28: 293000 | U28: 284000 | V28: 290000 | W28: =S28 | X28: 960 | Y28: =C28&X28 | Z28: =VLOOKUP(Y28,'Giá Uốn hiện tại'!$E:$F,2,0) | AA28: =W28-Z28 | AB28: =AA28/Z28
A29: 147 | B29: 99 Tân Sơn Nhì | C29: 99 TSN | D29: Hồ Chí Minh | E29: 18 | F29: Cụm gốc | G29: 0.6664 | H29: Cao | I29: 0.4415 | J29: Trung | K29: 218000 | L29: 200000 | M29: 299000 | N29: 0.25 | O29: 0.45 | P29: 225000 | Q29: 245000 | R29: 225k - 245k | S29: 225000 | T29: 245000 | U29: 235000 | V29: 242000 | W29: =S29 | X29: 960 | Y29: =C29&X29 | Z29: =VLOOKUP(Y29,'Giá Uốn hiện tại'!$E:$F,2,0) | AA29: =W29-Z29 | AB29: =AA29/Z29
A30: 182 | B30: 186 Đinh Tiên Hoàng | C30: 186 DTH | D30: Hồ Chí Minh | E30: 24 | F30: Cụm mới (cùng tỉnh) | G30: 0.6312 | H30: Cao | I30: 0.4414 | J30: Trung | K30: 218000 | L30: 203000 | M30: 299000 | N30: 0.25 | O30: 0.45 | P30: 227000 | Q30: 246000 | R30: 227k - 246k | S30: 227000 | T30: 246000 | U30: 237000 | V30: 243000 | W30: =S30 | X30: 960 | Y30: =C30&X30 | Z30: =VLOOKUP(Y30,'Giá Uốn hiện tại'!$E:$F,2,0) | AA30: =W30-Z30 | AB30: =AA30/Z30
A31: 184 | B31: 36 đường N1, KCN Mỹ Phước 1 | C31: 36 N1 BD | D31: Bình Dương | E31: 27 | F31: Cụm mới (cùng tỉnh) | G31: 0.553 | H31: Trung | I31: 0.3126 | J31: Thấp | K31: 218000 | L31: 299000 | M31: 348000 | N31: 0.25 | O31: 0.5 | P31: 311000 | Q31: 324000 | R31: 311k - 324k | S31: 311000 | T31: 324000 | U31: 317000 | V31: 322000 | W31: =S31 | X31: 960 | Y31: =C31&X31 | Z31: =VLOOKUP(Y31,'Giá Uốn hiện tại'!$E:$F,2,0) | AA31: =W31-Z31 | AB31: =AA31/Z31
A32: 188 | B32: 190 Hòa Bình | C32: 190 HB | D32: Hồ Chí Minh | E32: 22 | F32: Cụm mới (cùng tỉnh) | G32: 0.6785 | H32: Cao | I32: 0.412 | J32: Thấp | K32: 218000 | L32: 201000 | M32: 299000 | N32: 0.15 | O32: 0.35 | P32: 216000 | Q32: 235000 | R32: 216k - 235k | S32: 216000 | T32: 235000 | U32: 226000 | V32: 232000 | W32: =S32 | X32: 960 | Y32: =C32&X32 | Z32: =VLOOKUP(Y32,'Giá Uốn hiện tại'!$E:$F,2,0) | AA32: =W32-Z32 | AB32: =AA32/Z32
A33: 192 | B33: 264 Lạc Long Quân | C33: 264 LLQ | D33: Hà Nội | E33: 29 | F33: Cụm mới (cùng tỉnh) | G33: 0.5709 | H33: Trung | I33: 0.4294 | J33: Trung | K33: 229000 | L33: 204000 | M33: 401000 | N33: 0.4 | O33: 0.65 | P33: 283000 | Q33: 332000 | R33: 283k - 332k | S33: 283000 | T33: 332000 | U33: 307000 | V33: 325000 | W33: =S33 | X33: 960 | Y33: =C33&X33 | Z33: =VLOOKUP(Y33,'Giá Uốn hiện tại'!$E:$F,2,0) | AA33: =W33-Z33 | AB33: =AA33/Z33
A34: 193 | B34: 145 Tô Hiến Thành | C34: 145 THT | D34: Hồ Chí Minh | E34: 19 | F34: Cụm gốc | G34: 0.5476 | H34: Trung | I34: 0.4086 | J34: Thấp | K34: 218000 | L34: 202000 | M34: 300000 | N34: 0.25 | O34: 0.5 | P34: 226000 | Q34: 251000 | R34: 226k - 251k | S34: 226000 | T34: 251000 | U34: 239000 | V34: 247000 | W34: =S34 | X34: 960 | Y34: =C34&X34 | Z34: =VLOOKUP(Y34,'Giá Uốn hiện tại'!$E:$F,2,0) | AA34: =W34-Z34 | AB34: =AA34/Z34
... A37: 197 | B37: 65 Cầu Diễn | C37: 65 CD | D37: Hà Nội | E37: 30 | F37: Cụm mới (cùng tỉnh) | G37: 0.5089 | H37: Trung | I37: 0.3908 | J37: Thấp | K37: 218000 | L37: 204000 | M37: 347000 | N37: 0.25 | O37: 0.5 | P37: 240000 | Q37: 276000 | R37: 240k - 276k | S37: 240000 | T37: 276000 | U37: 258000 | V37: 270000 | W37: =S37 | X37: 960 | Y37: =C37&X37 | Z37: =VLOOKUP(Y37,'Giá Uốn hiện tại'!$E:$F,2,0) | AA37: =W37-Z37 | AB37: =AA37/Z37
A38: 199 | B38: 7 Đỗ Tường Phong | C38: 7 DTP LA | D38: Long An | F38: Độc lập (1 salon trong tỉnh) | G38: 0.5319 | H38: Trung | I38: 0.3842 | J38: Thấp | K38: 218000 | L38: 153000 | M38: 298000 | N38: 0.25 | O38: 0.5 | P38: 189000 | Q38: 226000 | R38: 189k - 226k | S38: 189000 | T38: 226000 | U38: 207000 | V38: 220000 | W38: =S38 | X38: 960 | Y38: =C38&X38 | Z38: =VLOOKUP(Y38,'Giá Uốn hiện tại'!$E:$F,2,0) | AA38: =W38-Z38 | AB38: =AA38/Z38
A39: 204 | B39: 401/1 Nguyễn Duy Trinh | C39: 401/1 NDT | D39: Hồ Chí Minh | E39: 23 | F39: Cụm mới (cùng tỉnh) | G39: 0.5599 | H39: Trung | I39: 0.3979 | J39: Thấp | K39: 218000 | L39: 203000 | M39: 300000 | N39: 0.25 | O39: 0.5 | P39: 227000 | Q39: 252000 | R39: 227k - 252k | S39: 227000 | T39: 252000 | U39: 239000 | V39: 248000 | W39: =S39 | X39: 960 | Y39: =C39&X39 | Z39: =VLOOKUP(Y39,'Giá Uốn hiện tại'!$E:$F,2,0) | AA39: =W39-Z39 | AB39: =AA39/Z39
A40: 205 | B40: 341 Xô Viết Nghệ Tĩnh | C40: 341 XVNT | D40: Hồ Chí Minh | E40: 17 | F40: Cụm gốc | G40: 0.6578 | H40: Cao | I40: 0.3726 | J40: Thấp | K40: 218000 | L40: 297000 | M40: 320000 | N40: 0.15 | O40: 0.35 | P40: 300000 | Q40: 305000 | R40: 300k - 305k | S40: 300000 | T40: 305000 | U40: 303000 | V40: 304000 | W40: =S40 | X40: 960 | Y40: =C40&X40 | Z40: =VLOOKUP(Y40,'Giá Uốn hiện tại'!$E:$F,2,0) | AA40: =W40-Z40 | AB40: =AA40/Z40
A41: 210 | B41: 148B Trương Định | C41: 148 TD | D41: Hà Nội | E41: 6 | F41: Cụm gốc | G41: 0.6448 | H41: Cao | I41: 0.361 | J41: Thấp | K41: 229000 | L41: 202000 | M41: 299000 | N41: 0.15 | O41: 0.35 | P41: 217000 | Q41: 236000 | R41: 217k - 236k | S41: 217000 | T41: 236000 | U41: 226000 | V41: 233000 | W41: =S41 | X41: 960 | Y41: =C41&X41 | Z41: =VLOOKUP(Y41,'Giá Uốn hiện tại'!$E:$F,2,0) | AA41: =W41-Z41 | AB41: =AA41/Z41
A42: 212 | B42: 58 Nguyễn Văn Cừ | C42: 58 NVC NA | D42: Nghệ An | E42: 10 | F42: Cụm gốc | G42: 0.5736 | H42: Trung | I42: 0.3468 | J42: Thấp | K42: 229000 | L42: 203000 | M42: 298000 | N42: 0.25 | O42: 0.5 | P42: 227000 | Q42: 250000 | R42: 227k - 250k | S42: 227000 | T42: 250000 | U42: 239000 | V42: 247000 | W42: =S42 | X42: 960 | Y42: =C42&X42 | Z42: =VLOOKUP(Y42,'Giá Uốn hiện tại'!$E:$F,2,0) | AA42: =W42-Z42 | AB42: =AA42/Z42
...

Sheet Nhuộm（Sao chép）
A1: SalonID | B1: Tên Salon | C1: Mã Salon | D1: GDTM đề xuất = KB1: Hút Traffic | E1: ID dv | G1: Giá hiện tại | H1: Chênh lệch giá cũ | I1: %
A2: 2 | B2: 346 Khâm Thiên | C2: 346 KT | D2: 255000 | E2: 960 | F2: 346 KT960 | G2: 369000 | H2: -114000 | I2: -0.30894309
A3: 11 | B3: 8 Châu Văn Liêm | C3: 8 CVL | D3: 226000 | E3: 960 | F3: 8 CVL960 | G3: 366000 | H3: -140000 | I3: -0.38251366
A4: 12 | B4: 12 Lê Đức Thọ | C4: 12 LDT | D4: 227000 | E4: 960 | F4: 12 LDT960 | G4: 366000 | H4: -139000 | I4: -0.37978142
A5: 20 | B5: 382 Nguyễn Trãi | C5: 382 NT | D5: 271000 | E5: 960 | F5: 382 NT960 | G5: 369000 | H5: -98000 | I5: -0.26558266
A6: 21 | B6: 575 Âu Cơ | C6: 575 AC | D6: 225000 | E6: 960 | F6: 575 AC960 | G6: 366000 | H6: -141000 | I6: -0.3852459
A7: 22 | B7: 927 Hậu Giang | C7: 927 HG | D7: 226000 | E7: 960 | F7: 927 HG960 | G7: 366000 | H7: -140000 | I7: -0.38251366
