Workbook

Sheet Sheet1
A1: SalonName | B1: P_Category_Name | C1: Phân nhóm | D1: name | E1: SalonId | F1: ServiceId | G1: Giá cũ Salon trước 31/12 | H1: Giá mới sau 31/12 | I1: Link menu online
A2: 10 TP | B2: DV_Dưỡng | C2: DV Dưỡng | D2: (2022T) ATS Control Buffer - Khử mùi tạo thơm cho tóc uốn nhuộm 40k | E2: 143 | F2: 610 | G2: 40000 | H2: 40000 | J2: =H2&H3&H4&H5&H6&H7&H8&H9&H10&H11&H12&H13&H14
A3: 10 TP | B3: DV_Uốn | C3: DV Uốn cao cấp (>340k) | D3: [DV] Uốn Texture con sâu/Uốn Ruffled | E3: 143 | F3: 674 | G3: 499000 | H3: 499000
A4: 10 TP | B4: DV_Uốn | C4: DV Duỗi Ép | D4: [DV] Ép side hai bên | E4: 143 | F4: 902 | G4: 189000 | H4: 209000
A5: 10 TP | B5: DV_Nhuộm | C5: DV Nhuộm tiêu chuẩn (<300k) | D5: [DV] Nhuộm đen phủ bạc R&B thảo dược | E5: 143 | F5: 912 | G5: 289000 | H5: 309000
A6: 10 TP | B6: DV_Nhuộm | C6: DV Nhuộm tiêu chuẩn (<300k) | D6: [DV] Tẩy tóc bật tông Ý (1 lần) | E6: 143 | F6: 915 | G6: 252000 | H6: 269000
A7: 10 TP | B7: DV_Nhuộm | C7: DV Nhuộm tiêu chuẩn (<300k) | D7: [DV] Tẩy tóc bật tông Ý (2 lần) 500k | E7: 143 | F7: 916 | G7: 500000 | H7: 529000
A8: 10 TP | B8: DV_Uốn | C8: DV Uốn cao cấp (>340k) | D8: Uốn định hình nếp tóc cao cấp (K-Perm Collection) | E8: 143 | F8: 952 | G8: 478000 | H8: 509000
A9: 10 TP | B9: DV_Nhuộm | C9: DV Nhuộm cao cấp (>300k) | D9: (NEW) Nhuộm màu thời trang Milano | E9: 143 | F9: 960 | G9: 332000 | H9: 369000
A10: 10 TP | B10: DV_Nhuộm | C10: DV Nhuộm tiêu chuẩn (<300k) | D10: (NEW) Nhuộm phủ bạc tiêu chuẩn 199K | E10: 143 | F10: 967 | G10: 199000 | H10: 209000
A11: 10 TP | B11: DV_Uốn | C11: DV Uốn tiêu chuẩn (<340k) | D11: (NEW) Uốn/Duỗi/Định hình full đầu tạo form vào nếp tự nhiên | E11: 143 | F11: 1009 | G11: 386000 | H11: 386000
A12: 10 TP | B12: DV_Dưỡng | C12: DV Dưỡng | D12: Phục hồi trẻ hóa Lipid Bond | E12: 143 | F12: 1101 | G12: 132000 | H12: 146000
A13: 10 TP | B13: DV_Uốn | C13: DV Uốn cao cấp (>340k) | D13: UỐN THIẾT KẾ PHỤC HỒI CHUYÊN SÂU LIPID BOND 2025 | E13: 143 | F13: 1148 | G13: 689000 | H13: 689000
A14: 10 TP | B14: DV_Nhuộm | C14: DV Nhuộm cao cấp (>300k) | D14: NHUỘM THIẾT KẾ PHỤC HỒI CHUYÊN SÂU LIPID BOND 2025 | E14: 143 | F14: 1149 | G14: 689000 | H14: 759000
A15: 103 TN | B15: DV_Dưỡng | C15: DV Dưỡng | D15: (2022T) ATS Control Buffer - Khử mùi tạo thơm cho tóc uốn nhuộm 40k | E15: 44 | F15: 610 | G15: 40000 | H15: 40000 | J15: =H15&H16&H17&H18&H19&H20&H21&H22&H23&H24&H25&H26&H27
A16: 103 TN | B16: DV_Uốn | C16: DV Uốn cao cấp (>340k) | D16: [DV] Uốn Texture con sâu/Uốn Ruffled | E16: 44 | F16: 674 | G16: 499000 | H16: 529000
A17: 103 TN | B17: DV_Uốn | C17: DV Duỗi Ép | D17: [DV] Ép side hai bên | E17: 44 | F17: 902 | G17: 189000 | H17: 209000
A18: 103 TN | B18: DV_Nhuộm | C18: DV Nhuộm tiêu chuẩn (<300k) | D18: [DV] Nhuộm đen phủ bạc R&B thảo dược | E18: 44 | F18: 912 | G18: 289000 | H18: 309000
A19: 103 TN | B19: DV_Nhuộm | C19: DV Nhuộm tiêu chuẩn (<300k) | D19: [DV] Tẩy tóc bật tông Ý (1 lần) | E19: 44 | F19: 915 | G19: 252000 | H19: 269000
A20: 103 TN | B20: DV_Nhuộm | C20: DV Nhuộm tiêu chuẩn (<300k) | D20: [DV] Tẩy tóc bật tông Ý (2 lần) 500k | E20: 44 | F20: 916 | G20: 500000 | H20: 529000
A21: 103 TN | B21: DV_Uốn | C21: DV Uốn cao cấp (>340k) | D21: Uốn định hình nếp tóc cao cấp (K-Perm Collection) | E21: 44 | F21: 952 | G21: 478000 | H21: 509000
A22: 103 TN | B22: DV_Nhuộm | C22: DV Nhuộm cao cấp (>300k) | D22: (NEW) Nhuộm màu thời trang Milano | E22: 44 | F22: 960 | G22: 332000 | H22: 349000
A23: 103 TN | B23: DV_Nhuộm | C23: DV Nhuộm tiêu chuẩn (<300k) | D23: (NEW) Nhuộm phủ bạc tiêu chuẩn 199K | E23: 44 | F23: 967 | G23: 199000 | H23: 209000
A24: 103 TN | B24: DV_Uốn | C24: DV Uốn tiêu chuẩn (<340k) | D24: (NEW) Uốn/Duỗi/Định hình full đầu tạo form vào nếp tự nhiên | E24: 44 | F24: 1009 | G24: 386000 | H24: 409000
A25: 103 TN | B25: DV_Dưỡng | C25: DV Dưỡng | D25: Phục hồi trẻ hóa Lipid Bond | E25: 44 | F25: 1101 | G25: 132000 | H25: 146000
A26: 103 TN | B26: DV_Uốn | C26: DV Uốn cao cấp (>340k) | D26: UỐN THIẾT KẾ PHỤC HỒI CHUYÊN SÂU LIPID BOND 2025 | E26: 44 | F26: 1148 | G26: 689000 | H26: 729000
A27: 103 TN | B27: DV_Nhuộm | C27: DV Nhuộm cao cấp (>300k) | D27: NHUỘM THIẾT KẾ PHỤC HỒI CHUYÊN SÂU LIPID BOND 2025 | E27: 44 | F27: 1149 | G27: 689000 | H27: 759000
A28: 103 TN | B28: DV_Uốn | C28: Combo UND | D28: Uốn/ Nhuộm thiết kế phục hồi 2025 | E28: 44 | F28: 1193 | G28: 1199000 | H28: 1199000
A29: 109 TQH | B29: DV_Dưỡng | C29: DV Dưỡng | D29: (2022T) ATS Control Buffer - Khử mùi tạo thơm cho tóc uốn nhuộm 40k | E29: 146 | F29: 610 | G29: 40000 | H29: 40000 | I29: https://drive.google.com/file/d/1qSZ5FPnQUnIC0tD74O41XAjMhFHj6wky/view?usp=drive_link | J29: =G29&G30&G31&G32&G33&G34&G35&G36&G37&G38&G39&G40&G41
A30: 109 TQH | B30: DV_Uốn | C30: DV Uốn cao cấp (>340k) | D30: [DV] Uốn Texture con sâu/Uốn Ruffled | E30: 146 | F30: 674 | G30: 499000 | H30: 529000
A31: 109 TQH | B31: DV_Uốn | C31: DV Duỗi Ép | D31: [DV] Ép side hai bên | E31: 146 | F31: 902 | G31: 189000 | H31: 209000
A32: 109 TQH | B32: DV_Nhuộm | C32: DV Nhuộm tiêu chuẩn (<300k) | D32: [DV] Nhuộm đen phủ bạc R&B thảo dược | E32: 146 | F32: 912 | G32: 289000 | H32: 309000
A33: 109 TQH | B33: DV_Nhuộm | C33: DV Nhuộm tiêu chuẩn (<300k) | D33: [DV] Tẩy tóc bật tông Ý (1 lần) | E33: 146 | F33: 915 | G33: 252000 | H33: 269000
A34: 109 TQH | B34: DV_Nhuộm | C34: DV Nhuộm tiêu chuẩn (<300k) | D34: [DV] Tẩy tóc bật tông Ý (2 lần) 500k | E34: 146 | F34: 916 | G34: 500000 | H34: 529000
A35: 109 TQH | B35: DV_Uốn | C35: DV Uốn cao cấp (>340k) | D35: Uốn định hình nếp tóc cao cấp (K-Perm Collection) | E35: 146 | F35: 952 | G35: 478000 | H35: 509000
A36: 109 TQH | B36: DV_Nhuộm | C36: DV Nhuộm cao cấp (>300k) | D36: (NEW) Nhuộm màu thời trang Milano | E36: 146 | F36: 960 | G36: 332000 | H36: 349000
A37: 109 TQH | B37: DV_Nhuộm | C37: DV Nhuộm tiêu chuẩn (<300k) | D37: (NEW) Nhuộm phủ bạc tiêu chuẩn 199K | E37: 146 | F37: 967 | G37: 199000 | H37: 209000
A38: 109 TQH | B38: DV_Uốn | C38: DV Uốn tiêu chuẩn (<340k) | D38: (NEW) Uốn/Duỗi/Định hình full đầu tạo form vào nếp tự nhiên | E38: 146 | F38: 1009 | G38: 386000 | H38: 409000
A39: 109 TQH | B39: DV_Dưỡng | C39: DV Dưỡng | D39: Phục hồi trẻ hóa Lipid Bond | E39: 146 | F39: 1101 | G39: 132000 | H39: 146000
A40: 109 TQH | B40: DV_Uốn | C40: DV Uốn cao cấp (>340k) | D40: UỐN THIẾT KẾ PHỤC HỒI CHUYÊN SÂU LIPID BOND 2025 | E40: 146 | F40: 1148 | G40: 689000 | H40: 729000
...

Sheet Bảng giá UND update 07.03.2026
A1: Tên salon | B1: ID salon | C1: Tên dịch vụ | D1: ID dịch vụ | F1: Giá cũ trước 31/12 | G1: Giá thay đổi ngày 31/12 | H1: Giá Tết thay đổi ngày 15-2 | I1: Điều chỉnh thay đổi ngày 6/3 (giá hiện tại) | J1: Note | L1: SalonId | M1: ServiceId | N1: Note thay đổi
A2: 10 TP | B2: =VLOOKUP(A2,'Sheet10'!$A:$C,3,0) | C2: (2022T) ATS Control Buffer - Khử mùi tạo thơm cho tóc uốn nhuộm 40k | D2: 610 | F2: 40000 | G2: 40000 | H2: 40000 | I2: 40000 | J2: Giá không đổi | K2: =G2-F2 | L2: 143 | M2: 610 | N2: Không đổi
A3: 10 TP | B3: =VLOOKUP(A3,'Sheet10'!$A:$C,3,0) | C3: (NEW) Nhuộm màu thời trang Milano | D3: 960 | E3: =A3&D3 | F3: 332000 | G3: 366000 | H3: 366000 | I3: 366000 | J3: Điều chỉnh giá | K3: =G3-F3 | L3: 143 | M3: 960 | N3: Không đổi
A4: 10 TP | B4: =VLOOKUP(A4,'Sheet10'!$A:$C,3,0) | C4: (NEW) Nhuộm phủ bạc tiêu chuẩn 199K | D4: 967 | F4: 199000 | G4: 199000 | H4: 199000 | I4: 199000 | J4: Giá không đổi | K4: =G4-F4 | L4: 143 | M4: 967 | N4: Không đổi
A5: 10 TP | B5: =VLOOKUP(A5,'Sheet10'!$A:$C,3,0) | C5: (NEW) Uốn/Duỗi/Định hình full đầu tạo form vào nếp tự nhiên | D5: =VLOOKUP(C5,'Sheet7'!$B:$C,2,0) | E5: =A5&D5 | F5: 386000 | G5: 386000 | H5: 396000 | I5: 396000 | J5: Giá không đổi | K5: =G5-F5 | L5: 143 | M5: 1009 | N5: +10.000 VNĐ
A6: 10 TP | B6: =VLOOKUP(A6,'Sheet10'!$A:$C,3,0) | C6: [DV] Nhuộm đen phủ bạc R&B thảo dược | D6: 912 | F6: 289000 | G6: 289000 | H6: 289000 | I6: 289000 | J6: Giá không đổi | K6: =G6-F6 | L6: 143 | M6: 912 | N6: Không đổi
A7: 10 TP | B7: =VLOOKUP(A7,'Sheet10'!$A:$C,3,0) | C7: [DV] Tẩy tóc bật tông Ý (1 lần) | D7: 915 | F7: 252000 | G7: 259000 | H7: 259000 | I7: 259000 | J7: Điều chỉnh giá | K7: =G7-F7 | L7: 143 | M7: 915 | N7: Không đổi
A8: 10 TP | B8: =VLOOKUP(A8,'Sheet10'!$A:$C,3,0) | C8: [DV] Tẩy tóc bật tông Ý (2 lần) 500k | D8: 916 | F8: 500000 | G8: 514000 | H8: 514000 | I8: 514000 | J8: Điều chỉnh giá | K8: =G8-F8 | L8: 143 | M8: 916 | N8: Không đổi
A9: 10 TP | B9: =VLOOKUP(A9,'Sheet10'!$A:$C,3,0) | C9: [DV] Uốn Texture con sâu/Uốn Ruffled | D9: =VLOOKUP(C9,'Sheet7'!$B:$C,2,0) | F9: 499000 | G9: 550000 | H9: 560000 | I9: 560000 | J9: Điều chỉnh giá | K9: =G9-F9 | L9: 143 | M9: 674 | N9: +10.000 VNĐ
A10: 10 TP | B10: =VLOOKUP(A10,'Sheet10'!$A:$C,3,0) | C10: [DV] Ép side hai bên | D10: =VLOOKUP(C10,'Sheet7'!$B:$C,2,0) | F10: 189000 | G10: 216000 | H10: 226000 | I10: 226000 | J10: Điều chỉnh giá | K10: =G10-F10 | L10: 143 | M10: 902 | N10: +10.000 VNĐ
A11: 10 TP | B11: =VLOOKUP(A11,'Sheet10'!$A:$C,3,0) | C11: NHUỘM THIẾT KẾ PHỤC HỒI CHUYÊN SÂU LIPID BOND 2025 | D11: 1149 | F11: 689000 | G11: 759000 | H11: 759000 | I11: 759000 | J11: Điều chỉnh giá | K11: =G11-F11 | L11: 143 | M11: 1149 | N11: Không đổi
A12: 10 TP | B12: =VLOOKUP(A12,'Sheet10'!$A:$C,3,0) | C12: Phục hồi trẻ hóa Lipid Bond | D12: 1101 | F12: 132000 | G12: 146000 | H12: 146000 | I12: 146000 | J12: Điều chỉnh giá | K12: =G12-F12 | L12: 143 | M12: 1101 | N12: Không đổi
A13: 10 TP | B13: =VLOOKUP(A13,'Sheet10'!$A:$C,3,0) | C13: UỐN THIẾT KẾ PHỤC HỒI CHUYÊN SÂU LIPID BOND 2025 | D13: =VLOOKUP(C13,'Sheet7'!$B:$C,2,0) | F13: 689000 | G13: 689000 | H13: 699000 | I13: 699000 | J13: Giá không đổi | K13: =G13-F13 | L13: 143 | M13: 1148 | N13: +10.000 VNĐ
A14: 10 TP | B14: =VLOOKUP(A14,'Sheet10'!$A:$C,3,0) | C14: Uốn định hình nếp tóc cao cấp (K-Perm Collection) | D14: =VLOOKUP(C14,'Sheet7'!$B:$C,2,0) | F14: 478000 | G14: 478000 | H14: 488000 | I14: 488000 | J14: Giá không đổi | K14: =G14-F14 | L14: 143 | M14: 952 | N14: +10.000 VNĐ
A15: 103 TN | B15: =VLOOKUP(A15,'Sheet10'!$A:$C,3,0) | C15: (2022T) ATS Control Buffer - Khử mùi tạo thơm cho tóc uốn nhuộm 40k | D15: 610 | F15: 40000 | G15: 40000 | H15: 40000 | I15: 40000 | J15: Giá không đổi | K15: =G15-F15 | L15: 44 | M15: 610 | N15: Không đổi
A16: 103 TN | B16: =VLOOKUP(A16,'Sheet10'!$A:$C,3,0) | C16: (NEW) Nhuộm màu thời trang Milano | D16: 960 | E16: =A16&D16 | F16: 332000 | G16: 369000 | H16: 369000 | I16: 369000 | J16: Điều chỉnh giá | K16: =G16-F16 | L16: 44 | M16: 960 | N16: Không đổi
A17: 103 TN | B17: =VLOOKUP(A17,'Sheet10'!$A:$C,3,0) | C17: (NEW) Nhuộm phủ bạc tiêu chuẩn 199K | D17: 967 | F17: 199000 | G17: 207000 | H17: 207000 | I17: 207000 | J17: Điều chỉnh giá | K17: =G17-F17 | L17: 44 | M17: 967 | N17: Không đổi
A18: 103 TN | B18: =VLOOKUP(A18,'Sheet10'!$A:$C,3,0) | C18: (NEW) Uốn/Duỗi/Định hình full đầu tạo form vào nếp tự nhiên | D18: =VLOOKUP(C18,'Sheet7'!$B:$C,2,0) | E18: =A18&D18 | F18: 386000 | G18: 406000 | H18: 416000 | I18: 406000 | J18: Điều chỉnh giá | K18: =G18-F18 | L18: 44 | M18: 1009 | N18: +10.000 VNĐ
A19: 103 TN | B19: =VLOOKUP(A19,'Sheet10'!$A:$C,3,0) | C19: [DV] Nhuộm đen phủ bạc R&B thảo dược | D19: 912 | F19: 289000 | G19: 299000 | H19: 299000 | I19: 299000 | J19: Điều chỉnh giá | K19: =G19-F19 | L19: 44 | M19: 912 | N19: Không đổi
A20: 103 TN | B20: =VLOOKUP(A20,'Sheet10'!$A:$C,3,0) | C20: [DV] Tẩy tóc bật tông Ý (1 lần) | D20: 915 | F20: 252000 | G20: 269000 | H20: 269000 | I20: 269000 | J20: Điều chỉnh giá | K20: =G20-F20 | L20: 44 | M20: 915 | N20: Không đổi
A21: 103 TN | B21: =VLOOKUP(A21,'Sheet10'!$A:$C,3,0) | C21: [DV] Tẩy tóc bật tông Ý (2 lần) 500k | D21: 916 | F21: 500000 | G21: 525000 | H21: 525000 | I21: 525000 | J21: Điều chỉnh giá | K21: =G21-F21 | L21: 44 | M21: 916 | N21: Không đổi
A22: 103 TN | B22: =VLOOKUP(A22,'Sheet10'!$A:$C,3,0) | C22: [DV] Uốn Texture con sâu/Uốn Ruffled | D22: =VLOOKUP(C22,'Sheet7'!$B:$C,2,0) | F22: 499000 | G22: 554000 | H22: 564000 | I22: 554000 | J22: Điều chỉnh giá | K22: =G22-F22 | L22: 44 | M22: 674 | N22: +10.000 VNĐ
A23: 103 TN | B23: =VLOOKUP(A23,'Sheet10'!$A:$C,3,0) | C23: [DV] Ép side hai bên | D23: =VLOOKUP(C23,'Sheet7'!$B:$C,2,0) | F23: 189000 | G23: 219000 | H23: 229000 | I23: 219000 | J23: Điều chỉnh giá | K23: =G23-F23 | L23: 44 | M23: 902 | N23: +10.000 VNĐ
A24: 103 TN | B24: =VLOOKUP(A24,'Sheet10'!$A:$C,3,0) | C24: NHUỘM THIẾT KẾ PHỤC HỒI CHUYÊN SÂU LIPID BOND 2025 | D24: 1149 | F24: 689000 | G24: 759000 | H24: 759000 | I24: 759000 | J24: Điều chỉnh giá | K24: =G24-F24 | L24: 44 | M24: 1149 | N24: Không đổi
A25: 103 TN | B25: =VLOOKUP(A25,'Sheet10'!$A:$C,3,0) | C25: Phục hồi trẻ hóa Lipid Bond | D25: 1101 | F25: 132000 | G25: 146000 | H25: 146000 | I25: 146000 | J25: Điều chỉnh giá | K25: =G25-F25 | L25: 44 | M25: 1101 | N25: Không đổi
A26: 103 TN | B26: =VLOOKUP(A26,'Sheet10'!$A:$C,3,0) | C26: UỐN THIẾT KẾ PHỤC HỒI CHUYÊN SÂU LIPID BOND 2025 | D26: =VLOOKUP(C26,'Sheet7'!$B:$C,2,0) | F26: 689000 | G26: 729000 | H26: 739000 | I26: 729000 | J26: Điều chỉnh giá | K26: =G26-F26 | L26: 44 | M26: 1148 | N26: +10.000 VNĐ
A27: 103 TN | B27: =VLOOKUP(A27,'Sheet10'!$A:$C,3,0) | C27: Uốn định hình nếp tóc cao cấp (K-Perm Collection) | D27: =VLOOKUP(C27,'Sheet7'!$B:$C,2,0) | F27: 478000 | G27: 502000 | H27: 512000 | I27: 502000 | J27: Điều chỉnh giá | K27: =G27-F27 | L27: 44 | M27: 952 | N27: +10.000 VNĐ
A28: 103 TN | B28: =VLOOKUP(A28,'Sheet10'!$A:$C,3,0) | C28: Uốn/ Nhuộm thiết kế phục hồi 2025 | F28: 1199000 | G28: 1199000 | H28: 1199000 | I28: 1199000 | J28: Giá không đổi | K28: =G28-F28 | L28: 44 | M28: 1193 | N28: Không đổi
A29: 109 TQH | B29: =VLOOKUP(A29,'Sheet10'!$A:$C,3,0) | C29: (2022T) ATS Control Buffer - Khử mùi tạo thơm cho tóc uốn nhuộm 40k | D29: 610 | F29: 40000 | G29: 40000 | H29: 40000 | I29: 40000 | J29: Giá không đổi | K29: =G29-F29 | L29: 146 | M29: 610 | N29: Không đổi
A30: 109 TQH | B30: =VLOOKUP(A30,'Sheet10'!$A:$C,3,0) | C30: (NEW) Nhuộm màu thời trang Milano | D30: 960 | E30: =A30&D30 | F30: 332000 | G30: 366000 | H30: 366000 | I30: 366000 | J30: Điều chỉnh giá | K30: =G30-F30 | L30: 146 | M30: 960 | N30: Không đổi
A31: 109 TQH | B31: =VLOOKUP(A31,'Sheet10'!$A:$C,3,0) | C31: (NEW) Nhuộm phủ bạc tiêu chuẩn 199K | D31: 967 | F31: 199000 | G31: 227000 | H31: 227000 | I31: 227000 | J31: Điều chỉnh giá | K31: =G31-F31 | L31: 146 | M31: 967 | N31: Không đổi
A32: 109 TQH | B32: =VLOOKUP(A32,'Sheet10'!$A:$C,3,0) | C32: (NEW) Uốn/Duỗi/Định hình full đầu tạo form vào nếp tự nhiên | D32: =VLOOKUP(C32,'Sheet7'!$B:$C,2,0) | E32: =A32&D32 | F32: 386000 | G32: 386000 | H32: 396000 | I32: 396000 | J32: Giá không đổi | K32: =G32-F32 | L32: 146 | M32: 1009 | N32: +10.000 VNĐ
A33: 109 TQH | B33: =VLOOKUP(A33,'Sheet10'!$A:$C,3,0) | C33: [DV] Nhuộm đen phủ bạc R&B thảo dược | D33: 912 | F33: 289000 | G33: 329000 | H33: 329000 | I33: 329000 | J33: Điều chỉnh giá | K33: =G33-F33 | L33: 146 | M33: 912 | N33: Không đổi
A34: 109 TQH | B34: =VLOOKUP(A34,'Sheet10'!$A:$C,3,0) | C34: [DV] Tẩy tóc bật tông Ý (1 lần) | D34: 915 | F34: 252000 | G34: 259000 | H34: 259000 | I34: 259000 | J34: Điều chỉnh giá | K34: =G34-F34 | L34: 146 | M34: 915 | N34: Không đổi
A35: 109 TQH | B35: =VLOOKUP(A35,'Sheet10'!$A:$C,3,0) | C35: [DV] Tẩy tóc bật tông Ý (2 lần) 500k | D35: 916 | F35: 500000 | G35: 514000 | H35: 514000 | I35: 514000 | J35: Điều chỉnh giá | K35: =G35-F35 | L35: 146 | M35: 916 | N35: Không đổi
A36: 109 TQH | B36: =VLOOKUP(A36,'Sheet10'!$A:$C,3,0) | C36: [DV] Uốn Texture con sâu/Uốn Ruffled | D36: =VLOOKUP(C36,'Sheet7'!$B:$C,2,0) | F36: 499000 | G36: 550000 | H36: 560000 | I36: 560000 | J36: Điều chỉnh giá | K36: =G36-F36 | L36: 146 | M36: 674 | N36: +10.000 VNĐ
A37: 109 TQH | B37: =VLOOKUP(A37,'Sheet10'!$A:$C,3,0) | C37: [DV] Ép side hai bên | D37: =VLOOKUP(C37,'Sheet7'!$B:$C,2,0) | F37: 189000 | G37: 189000 | H37: 199000 | I37: 199000 | J37: Giá không đổi | K37: =G37-F37 | L37: 146 | M37: 902 | N37: +10.000 VNĐ
A38: 109 TQH | B38: =VLOOKUP(A38,'Sheet10'!$A:$C,3,0) | C38: NHUỘM THIẾT KẾ PHỤC HỒI CHUYÊN SÂU LIPID BOND 2025 | D38: 1149 | F38: 689000 | G38: 759000 | H38: 759000 | I38: 759000 | J38: Điều chỉnh giá | K38: =G38-F38 | L38: 146 | M38: 1149 | N38: Không đổi
A39: 109 TQH | B39: =VLOOKUP(A39,'Sheet10'!$A:$C,3,0) | C39: Phục hồi trẻ hóa Lipid Bond | D39: 1101 | F39: 132000 | G39: 146000 | H39: 146000 | I39: 146000 | J39: Điều chỉnh giá | K39: =G39-F39 | L39: 146 | M39: 1101 | N39: Không đổi
A40: 109 TQH | B40: =VLOOKUP(A40,'Sheet10'!$A:$C,3,0) | C40: UỐN THIẾT KẾ PHỤC HỒI CHUYÊN SÂU LIPID BOND 2025 | D40: =VLOOKUP(C40,'Sheet7'!$B:$C,2,0) | F40: 689000 | G40: 689000 | H40: 699000 | I40: 699000 | J40: Giá không đổi | K40: =G40-F40 | L40: 146 | M40: 1148 | N40: +10.000 VNĐ
...

Sheet Bảng giá DV Relax _ Spa _ SC cậ
A1: ID Salon | B1: Salon | C1: Nhóm ngành | D1: ID DV | E1: Tên dịch vụ | F1: Giá cũ trước 14.3 | G1: Giá ngày 14.3 | H1: Giá mới ngày 24.3 (giá hiện tại) | J1: Giá mới ngày 24.3
A2: 143 | B2: 10 TP | C2: DV_Cắt | D2: 513 | E2: [DV] ShineCombo 10 bước Ultra Care 2023 | F2: 122000 | G2: 122000 | H2: 122000 | I2: =A2&D2 | J2: 122000
A3: 143 | B3: 10 TP | C3: DV_Cắt | D3: 891 | E3: Cắt xả tạo kiểu | F3: 94000 | G3: 95000 | H3: 95000 | I3: =A3&D3 | J3: 95000
A4: 143 | B4: 10 TP | C4: DV_Cắt | D4: 1002 | E4: Kid Cắt | F4: 75000 | G4: 76000 | H4: 76000 | I4: =A4&D4 | J4: 76000
A5: 143 | B5: 10 TP | C5: DV_Cắt | D5: 1052 | E5: Combo 1 - First Class 1 | F5: 139000 | G5: 139000 | H5: 139000 | I5: =A5&D5 | J5: 139000
A6: 143 | B6: 10 TP | C6: DV_Cắt | D6: 1070 | E6: Combo Cắt gội Kid | F6: 100000 | G6: 101000 | H6: 101000 | I6: =A6&D6 | J6: 101000
A7: 143 | B7: 10 TP | C7: DV_Cắt_Vip | D7: 1046 | E7: Shinecombo 2 | F7: 199000 | G7: 201000 | H7: 201000 | I7: =A7&D7 | J7: 201000
A8: 143 | B8: 10 TP | C8: DV_Cắt_Vip | D8: 1047 | E8: Cắt Gội Combo 3 - Chăm da | F8: 299000 | G8: 302000 | H8: 302000 | I8: =A8&D8 | J8: 302000
A9: 143 | B9: 10 TP | C9: DV_Cắt_Vip | D9: 1048 | E9: Combo 4 | F9: 389000 | G9: 393000 | H9: 393000 | I9: =A9&D9 | J9: 393000
A10: 143 | B10: 10 TP | C10: DV_Cắt_Vip | D10: 1053 | E10: Combo 2 - First Class 2 | F10: 239000 | G10: 242000 | H10: 242000 | I10: =A10&D10 | J10: 242000
A11: 143 | B11: 10 TP | C11: DV_Cắt_Vip | D11: 1054 | E11: Combo 3 - First Class 3 | F11: 309000 | G11: 312000 | H11: 312000 | I11: =A11&D11 | J11: 312000
A12: 143 | B12: 10 TP | C12: DV_Cắt_Vip | D12: 1055 | E12: Combo 4- First Class 4 | F12: 409000 | G12: 413000 | H12: 413000 | I12: =A12&D12 | J12: 413000
A13: 143 | B13: 10 TP | C13: DV_Cắt_Vip | D13: 1064 | E13: Cắt Gội Combo 5 - Dưỡng sinh | F13: 459000 | G13: 464000 | H13: 464000 | I13: =A13&D13 | J13: 464000
... A73: 244 | B73: 11 PKT | C73: DV_Cắt | D73: 1070 | E73: Combo Cắt gội Kid | F73: 100000 | G73: 104000 | H73: 104000 | I73: =A73&D73 | J73: 104000
A74: 244 | B74: 11 PKT | C74: DV_Cắt_Vip | D74: 1046 | E74: Shinecombo 2 | F74: 205000 | G74: 213000 | H74: 209000 | I74: =A74&D74 | J74: =VLOOKUP(I74,#REF!,2,0)
A75: 244 | B75: 11 PKT | C75: DV_Cắt_Vip | D75: 1047 | E75: Cắt Gội Combo 3 - Chăm da | F75: 305000 | G75: 317000 | H75: 309000 | I75: =A75&D75 | J75: =VLOOKUP(I75,#REF!,2,0)
A76: 244 | B76: 11 PKT | C76: DV_Cắt_Vip | D76: 1048 | E76: Combo 4 | F76: 395000 | G76: 411000 | H76: 411000 | I76: =A76&D76 | J76: 411000
A77: 244 | B77: 11 PKT | C77: DV_Cắt_Vip | D77: 1064 | E77: Cắt Gội Combo 5 - Dưỡng sinh | F77: 459000 | G77: 477000 | H77: 477000 | I77: =A77&D77 | J77: 477000
A78: 244 | B78: 11 PKT | C78: DV_Cắt_Vip | D78: 1065 | E78: Cắt Gội Combo 3 - Dưỡng sinh | F78: 305000 | G78: 317000 | H78: 317000 | I78: =A78&D78 | J78: 317000
A79: 244 | B79: 11 PKT | C79: DV_Gội | D79: 867 | E79: Gội dưỡng sinh cổ vai gáy | F79: 99000 | G79: 103000 | H79: 99000 | I79: =A79&D79 | J79: =VLOOKUP(I79,#REF!,2,0)
A80: 244 | B80: 11 PKT | C80: DV_Gội | D80: 930 | E80: [NEW] Gội dưỡng sinh cổ vai gáy và chăm sóc da | F80: 139000 | G80: 145000 | H80: 139000 | I80: =A80&D80 | J80: =VLOOKUP(I80,#REF!,2,0)
A81: 244 | B81: 11 PKT | C81: DV_Gội | D81: 934 | E81: Gội combo 3 - Dưỡng sinh | F81: 229000 | G81: 238000 | H81: 238000 | I81: =A81&D81 | J81: 238000
A82: 244 | B82: 11 PKT | C82: DV_Gội | D82: 940 | E82: [NEW] Gội dưỡng sinh | F82: 59000 | G82: 61000 | H82: 59000 | I82: =A82&D82 | J82: =VLOOKUP(I82,#REF!,2,0)
A83: 244 | B83: 11 PKT | C83: DV_Gội | D83: 1058 | E83: Gội Combo 2 | F83: 159000 | G83: 165000 | H83: 165000 | I83: =A83&D83 | J83: 165000
A84: 244 | B84: 11 PKT | C84: DV_Gội | D84: 1059 | E84: Gội Combo 3 - Chăm da | F84: 239000 | G84: 249000 | H84: 243000 | I84: =A84&D84 | J84: =VLOOKUP(I84,#REF!,2,0)
A85: 244 | B85: 11 PKT | C85: DV_Gội | D85: 1060 | E85: Gội Combo 4 | F85: 289000 | G85: 302000 | H85: 289000 | I85: =A85&D85 | J85: =VLOOKUP(I85,#REF!,2,0)
A86: 244 | B86: 11 PKT | C86: DV_Gội | D86: 1066 | E86: Gội trải nghiệm 75p | F86: 589000 | G86: 613000 | H86: 594000 | I86: =A86&D86 | J86: =VLOOKUP(I86,#REF!,2,0)
A87: 244 | B87: 11 PKT | C87: DV_Gội | D87: 1067 | E87: Gội trải nghiệm 90p | F87: 789000 | G87: 821000 | H87: 821000 | I87: =A87&D87 | J87: 821000
A88: 244 | B88: 11 PKT | C88: DV_Gội | D88: 1068 | E88: Gội trải nghiệm 115p | F88: 999000 | G88: 1039000 | H88: 1039000 | I88: =A88&D88 | J88: 1039000
A89: 244 | B89: 11 PKT | C89: DV_Gội | D89: 1069 | E89: Gội trải nghiệm 140p | F89: 1199000 | G89: 1247000 | H89: 1247000 | I89: =A89&D89 | J89: 1247000
A90: 72 | B90: 113 THD AG | C90: DV_Cắt | D90: 513 | E90: [DV] ShineCombo 10 bước Ultra Care 2023 | F90: 122000 | G90: 122000 | H90: 122000 | I90: =A90&D90 | J90: 122000
A91: 72 | B91: 113 THD AG | C91: DV_Cắt | D91: 891 | E91: Cắt xả tạo kiểu | F91: 94000 | G91: 94000 | H91: 94000 | I91: =A91&D91 | J91: 94000
A92: 72 | B92: 113 THD AG | C92: DV_Cắt | D92: 1002 | E92: Kid Cắt | F92: 75000 | G92: 75000 | H92: 75000 | I92: =A92&D92 | J92: 75000
A93: 72 | B93: 113 THD AG | C93: DV_Cắt | D93: 1070 | E93: Combo Cắt gội Kid | F93: 100000 | G93: 100000 | H93: 100000 | I93: =A93&D93 | J93: 100000
A94: 72 | B94: 113 THD AG | C94: DV_Cắt_Vip | D94: 1046 | E94: Shinecombo 2 | F94: 199000 | G94: 199000 | H94: 199000 | I94: =A94&D94 | J94: 199000
A95: 72 | B95: 113 THD AG | C95: DV_Cắt_Vip | D95: 1047 | E95: Cắt Gội Combo 3 - Chăm da | F95: 299000 | G95: 299000 | H95: 299000 | I95: =A95&D95 | J95: 299000
A96: 72 | B96: 113 THD AG | C96: DV_Cắt_Vip | D96: 1048 | E96: Combo 4 | F96: 389000 | G96: 389000 | H96: 389000 | I96: =A96&D96 | J96: 389000
A97: 72 | B97: 113 THD AG | C97: DV_Cắt_Vip | D97: 1064 | E97: Cắt Gội Combo 5 - Dưỡng sinh | F97: 459000 | G97: 459000 | H97: 459000 | I97: =A97&D97 | J97: 459000
A98: 72 | B98: 113 THD AG | C98: DV_Cắt_Vip | D98: 1065 | E98: Cắt Gội Combo 3 - Dưỡng sinh | F98: 299000 | G98: 299000 | H98: 299000 | I98: =A98&D98 | J98: 299000
... A216: 247 | B216: 1371 PVT | C216: DV_Gội | D216: 1059 | E216: Gội Combo 3 - Chăm da | F216: 239000 | G216: 239000 | H216: 239000 | I216: =A216&D216 | J216: 239000
...

Sheet Giá DV Cắt-Relax có Cắt update 
A1: GIÁ DỊCH VỤ CẮT XẢ VÀ CÁC DỊCH VỤ RELAX CÓ CẮT
A2: Salon_name | B2: P_Category_name | C2: service_id | D2: service_name | E2: Giá cũ | F2: Giá mới triển khai 1/2/2026 | G2: Chênh lệch điều chỉnh | H2: Note | I2: Giá mới điều chỉnh ngày 07/03
A3: 10 TP | B3: DV_Cắt | C3: 513 | D3: [DV] ShineCombo 10 bước Ultra Care 2023 | E3: 122000 | F3: 122000 | G3: =F3-E3 | I3: 122000
A4: 10 TP | B4: DV_Cắt | C4: 891 | D4: Cắt xả tạo kiểu | E4: 94000 | F4: 94000 | G4: =F4-E4 | I4: 94000
A5: 10 TP | B5: DV_Cắt | C5: 1052 | D5: Combo 1 - First Class 1 | E5: 139000 | F5: 139000 | G5: =F5-E5 | I5: 139000
A6: 10 TP | B6: DV_Cắt | C6: 1002 | D6: Kid Cắt | E6: 75000 | F6: 75000 | G6: =F6-E6 | I6: 75000
A7: 10 TP | B7: DV_Cắt_Vip | C7: 1047 | D7: Cắt Gội Combo 3 - Chăm da | E7: 299000 | F7: 299000 | G7: =F7-E7 | I7: 299000
A8: 10 TP | B8: DV_Cắt_Vip | C8: 1053 | D8: Combo 2 - First Class 2 | E8: 239000 | F8: 239000 | G8: =F8-E8 | I8: 239000
A9: 10 TP | B9: DV_Cắt_Vip | C9: 1054 | D9: Combo 3 - First Class 3 | E9: 309000 | F9: 309000 | G9: =F9-E9 | I9: 309000
A10: 10 TP | B10: DV_Cắt_Vip | C10: 1055 | D10: Combo 4- First Class 4 | E10: 409000 | F10: 409000 | G10: =F10-E10 | I10: 409000
A11: 10 TP | B11: DV_Cắt_Vip | C11: 1046 | D11: Shinecombo 2 | E11: 199000 | F11: 199000 | G11: =F11-E11 | I11: 199000
A12: 103 TN | B12: DV_Cắt | C12: 513 | D12: [DV] ShineCombo 10 bước Ultra Care 2023 | E12: 122000 | F12: 122000 | G12: =F12-E12 | I12: 122000
A13: 103 TN | B13: DV_Cắt | C13: 1070 | D13: Combo Cắt gội Kid | E13: 100000 | F13: 100000 | G13: =F13-E13 | I13: 100000
A14: 103 TN | B14: DV_Cắt | C14: 891 | D14: Cắt xả tạo kiểu | E14: 94000 | F14: 95000 | G14: =F14-E14 | H14: điều chỉnh giá | I14: 95000
A15: 103 TN | B15: DV_Cắt | C15: 1052 | D15: Combo 1 - First Class 1 | E15: 139000 | F15: 139000 | G15: =F15-E15 | I15: 139000
A16: 103 TN | B16: DV_Cắt | C16: 1002 | D16: Kid Cắt | E16: 75000 | F16: 76000 | G16: =F16-E16 | H16: điều chỉnh giá | I16: 76000
A17: 103 TN | B17: DV_Cắt_Vip | C17: 1047 | D17: Cắt Gội Combo 3 - Chăm da | E17: 299000 | F17: 300000 | G17: =F17-E17 | H17: điều chỉnh giá | I17: 300000
A18: 103 TN | B18: DV_Cắt_Vip | C18: 1065 | D18: Cắt Gội Combo 3 - Dưỡng sinh | E18: 299000 | F18: 300000 | G18: =F18-E18 | H18: điều chỉnh giá | I18: 300000
A19: 103 TN | B19: DV_Cắt_Vip | C19: 1053 | D19: Combo 2 - First Class 2 | E19: 239000 | F19: 240000 | G19: =F19-E19 | H19: điều chỉnh giá | I19: 240000
A20: 103 TN | B20: DV_Cắt_Vip | C20: 1054 | D20: Combo 3 - First Class 3 | E20: 309000 | F20: 310000 | G20: =F20-E20 | H20: điều chỉnh giá | I20: 310000
A21: 103 TN | B21: DV_Cắt_Vip | C21: 1048 | D21: Combo 4 | E21: 389000 | F21: 390000 | G21: =F21-E21 | H21: điều chỉnh giá | I21: 390000
A22: 103 TN | B22: DV_Cắt_Vip | C22: 1055 | D22: Combo 4- First Class 4 | E22: 409000 | F22: 410000 | G22: =F22-E22 | H22: điều chỉnh giá | I22: 410000
A23: 103 TN | B23: DV_Cắt_Vip | C23: 1046 | D23: Shinecombo 2 | E23: 199000 | F23: 200000 | G23: =F23-E23 | H23: điều chỉnh giá | I23: 200000
A24: 109 TQH | B24: DV_Cắt | C24: 513 | D24: [DV] ShineCombo 10 bước Ultra Care 2023 | E24: 122000 | F24: 122000 | G24: =F24-E24 | I24: 122000
A25: 109 TQH | B25: DV_Cắt | C25: 891 | D25: Cắt xả tạo kiểu | E25: 94000 | F25: 94000 | G25: =F25-E25 | I25: 94000
A26: 109 TQH | B26: DV_Cắt | C26: 1002 | D26: Kid Cắt | E26: 75000 | F26: 75000 | G26: =F26-E26 | I26: 75000
A27: 109 TQH | B27: DV_Cắt_Vip | C27: 1047 | D27: Cắt Gội Combo 3 - Chăm da | E27: 299000 | F27: 299000 | G27: =F27-E27 | I27: 299000
A28: 109 TQH | B28: DV_Cắt_Vip | C28: 1065 | D28: Cắt Gội Combo 3 - Dưỡng sinh | E28: 299000 | F28: 299000 | G28: =F28-E28 | I28: 299000
A29: 109 TQH | B29: DV_Cắt_Vip | C29: 1048 | D29: Combo 4 | E29: 389000 | F29: 389000 | G29: =F29-E29 | I29: 389000
A30: 109 TQH | B30: DV_Cắt_Vip | C30: 1046 | D30: Shinecombo 2 | E30: 199000 | F30: 199000 | G30: =F30-E30 | I30: 199000
A31: 11 PKT | B31: DV_Cắt | C31: 513 | D31: [DV] ShineCombo 10 bước Ultra Care 2023 | E31: 122000 | F31: 122000 | G31: =F31-E31 | I31: 122000
A32: 11 PKT | B32: DV_Cắt | C32: 1070 | D32: Combo Cắt gội Kid | E32: 100000 | F32: 100000 | G32: =F32-E32 | I32: 100000
A33: 11 PKT | B33: DV_Cắt | C33: 891 | D33: Cắt xả tạo kiểu | E33: 94000 | F33: 100000 | G33: =F33-E33 | H33: điều chỉnh giá | I33: 100000
A34: 11 PKT | B34: DV_Cắt | C34: 1052 | D34: Combo 1 - First Class 1 | E34: 159000 | F34: 159000 | G34: =F34-E34 | I34: 159000
A35: 11 PKT | B35: DV_Cắt | C35: 1002 | D35: Kid Cắt | E35: 75000 | F35: 81000 | G35: =F35-E35 | H35: điều chỉnh giá | I35: 81000
A36: 11 PKT | B36: DV_Cắt_Vip | C36: 1047 | D36: Cắt Gội Combo 3 - Chăm da | E36: 299000 | F36: 305000 | G36: =F36-E36 | H36: điều chỉnh giá | I36: 305000
A37: 11 PKT | B37: DV_Cắt_Vip | C37: 1065 | D37: Cắt Gội Combo 3 - Dưỡng sinh | E37: 299000 | F37: 305000 | G37: =F37-E37 | H37: điều chỉnh giá | I37: 305000
A38: 11 PKT | B38: DV_Cắt_Vip | C38: 1053 | D38: Combo 2 - First Class 2 | E38: 229000 | F38: 235000 | G38: =F38-E38 | H38: điều chỉnh giá | I38: 235000
A39: 11 PKT | B39: DV_Cắt_Vip | C39: 1054 | D39: Combo 3 - First Class 3 | E39: 299000 | F39: 305000 | G39: =F39-E39 | H39: điều chỉnh giá | I39: 305000
A40: 11 PKT | B40: DV_Cắt_Vip | C40: 1048 | D40: Combo 4 | E40: 389000 | F40: 395000 | G40: =F40-E40 | H40: điều chỉnh giá | I40: 395000
...

Sheet CR Uốn Nhuộm Dưỡng ngày 1 đến 1
A1: CR Uốn Nhuộm Dưỡng ngày 1 đến 14 tháng 1 so sánh với 14 ngày trước đó tháng 12 (từ 17-31/12)
A3: Salon_name | B3: CR %UND | C3: CR %UND tăng giảm với kì so sánh | D3: m_%Uon | E3: m_%uon_ss | F3: m_%Nhuom | G3: m_%nhuom_ss | H3: m_%Duong | I3: m_%duong_ss
A4: 451 PVT | B4: 17,38% | C4: 7,68% | D4: 9,57% | E4: 3,51% | F4: 3,53% | G4: 2,52% | H4: 4,28% | I4: 1,66%
A5: 103 TN | B5: 10,82% | C5: -0,63% | D5: 5,08% | E5: -1,17% | F5: 3,51% | G5: -0,21% | H5: 2,24% | I5: 0,75%
A6: 401/1 NDT | B6: 6,83% | C6: -3,52% | D6: 4,32% | E6: -1,07% | F6: 1,44% | G6: -1,26% | H6: 1,08% | I6: -1,19%
A7: 29 HB | B7: 9,87% | C7: 2,20% | D7: 6,28% | E7: 1,01% | F7: 2,24% | G7: 0,81% | H7: 1,35% | I7: 0,39%
A8: 10 TP | B8: 12,50% | C8: -0,48% | D8: 6,74% | E8: -0,53% | F8: 2,33% | G8: 0,29% | H8: 3,43% | I8: -0,25%
A9: 109 TQH | B9: 8,95% | C9: -2,62% | D9: 4,37% | E9: -0,66% | F9: 1,49% | G9: -1,02% | H9: 3,09% | I9: -0,95%
A10: 11 PKT | B10: 12,81% | C10: -2,29% | D10: 6,82% | E10: -1,17% | F10: 3,31% | G10: 1,17% | H10: 2,69% | I10: -2,29%
A11: 113 THD AG | B11: 8,27% | C11: 2,92% | D11: 4,27% | E11: 1,72% | F11: 2,93% | G11: 0,64% | H11: 1,07% | I11: 0,56%
A12: 1146 KVC | B12: 8,83% | C12: -2,02% | D12: 6,57% | E12: 0,50% | F12: 1,03% | G12: -0,81% | H12: 1,23% | I12: -1,71%
A13: 116 TK | B13: 10,15% | C13: -0,22% | D13: 4,87% | E13: 0,24% | F13: 1,43% | G13: -0,05% | H13: 3,86% | I13: -0,41%
A14: 1180 QT | B14: 8,59% | C14: -0,53% | D14: 5,94% | E14: 0,27% | F14: 1,88% | G14: -0,10% | H14: 0,78% | I14: -0,70%
... A30: 264 LLQ | B30: 15,22% | C30: -0,89% | D30: 6,99% | E30: 0,21% | F30: 3,11% | G30: 0,55% | H30: 5,12% | I30: -1,65%
A31: 290 QT TH | B31: 7,14% | C31: -1,40% | D31: 5,95% | E31: 0,56% | F31: 1,19% | G31: -0,83% | I31: -1,12%
A32: 304 NT TH | B32: 9,46% | C32: -2,37% | D32: 6,31% | E32: -0,70% | F32: 1,89% | G32: -1,25% | H32: 1,26% | I32: -0,43%
A33: 312 LVS | B33: 9,54% | C33: 0,94% | D33: 4,98% | E33: -0,10% | F33: 2,95% | G33: 0,52% | H33: 1,61% | I33: 0,52%
A34: 32 NAT | B34: 12,75% | C34: -3,57% | D34: 6,49% | E34: -0,86% | F34: 2,46% | G34: 0,22% | H34: 3,80% | I34: -2,93%
A35: 341 XVNT | B35: 8,96% | C35: 1,54% | D35: 2,79% | E35: -0,08% | F35: 2,59% | G35: 0,57% | H35: 3,59% | I35: 1,06%
A36: 346 KT | B36: 18,18% | C36: 1,86% | D36: 6,73% | E36: -0,89% | F36: 4,73% | G36: 2,96% | H36: 6,73% | I36: -0,21%
A37: 36 N1 BD | B37: 6,62% | C37: 2,31% | D37: 4,60% | E37: 2,11% | F37: 1,65% | G37: 0,16% | H37: 0,37% | I37: 0,04%
A38: 362 NGT BN | B38: 9,89% | C38: -3,02% | D38: 6,29% | E38: -0,03% | F38: 1,40% | G38: -1,68% | H38: 2,20% | I38: -1,31%
A39: 363 LNQ TN | B39: 6,37% | C39: -3,86% | D39: 2,83% | E39: -0,53% | F39: 1,24% | G39: -1,66% | H39: 2,30% | I39: -1,67%
A40: 382 NT | B40: 16,97% | C40: 3,81% | D40: 7,18% | E40: 1,72% | F40: 2,18% | G40: 0,38% | H40: 7,61% | I40: 1,71%
A41: 39 HBT | B41: 13,45% | C41: 5,08% | D41: 6,92% | E41: 3,17% | F41: 2,61% | G41: 0,98% | H41: 3,92% | I41: 0,94%
A42: 4 LQD BN | B42: 5,09% | C42: -0,07% | D42: 3,27% | E42: 1,37% | F42: 1,45% | G42: -0,99% | H42: 0,36% | I42: -0,45%
A43: 420 HTP | B43: 5,76% | C43: -0,84% | D43: 3,44% | E43: 0,27% | F43: 1,84% | G43: -0,72% | H43: 0,48% | I43: -0,40%
... A47: 575 AC | B47: 6,82% | C47: -0,17% | D47: 4,11% | E47: 0,36% | F47: 1,95% | G47: 0,11% | H47: 0,76% | I47: -0,64%
A48: 58 NVC NA | B48: 9,07% | C48: 0,25% | D48: 6,85% | E48: 0,24% | F48: 2,22% | G48: 0,31% | I48: -0,29%
A49: 595 BT TH | B49: 6,39% | C49: -0,07% | D49: 2,56% | E49: -0,80% | F49: 1,60% | G49: 0,82% | H49: 2,24% | I49: -0,09%
A50: 62 LH | B50: 14,06% | C50: -0,47% | D50: 4,95% | E50: 0,11% | F50: 2,57% | G50: -0,13% | H50: 6,53% | I50: -0,45%
A51: 65 CD | B51: 14,72% | C51: 3,38% | D51: 5,84% | E51: 1,51% | F51: 2,03% | G51: 0,17% | H51: 6,85% | I51: 1,70%
A52: 68 LN NA | B52: 5,79% | C52: 1,30% | D52: 5,26% | E52: 2,41% | F52: 0,53% | G52: -1,11%
A53: 7 DTP LA | B53: 9,65% | C53: 0,35% | D53: 4,00% | E53: 0,90% | F53: 2,35% | G53: 0,49% | H53: 3,29% | I53: -1,04%
A54: 708 LTT | B54: 8,96% | C54: 2,84% | D54: 5,30% | E54: 2,00% | F54: 2,24% | G54: -0,43% | H54: 1,43% | I54: 1,27%
A55: 730 TL10 | B55: 6,48% | C55: 0,73% | D55: 3,24% | E55: 0,06% | F55: 2,19% | G55: 1,03% | H55: 1,05% | I55: -0,35%
A56: 76 PVH | B56: 9,40% | C56: -1,54% | D56: 5,24% | E56: 1,65% | F56: 1,45% | G56: -3,35% | H56: 2,71% | I56: 0,16%
A57: 8 CVL | B57: 10,84% | C57: -0,32% | D57: 6,68% | E57: 0,38% | F57: 2,71% | G57: -0,58% | H57: 1,45% | I57: -0,12%
A58: 80 PL BD | B58: 9,92% | C58: 1,54% | D58: 7,01% | E58: 1,24% | F58: 2,51% | G58: 0,55% | H58: 0,40% | I58: -0,26%
A59: 80 TP TH | B59: 9,78% | C59: 3,64% | D59: 5,56% | E59: 1,91% | F59: 1,78% | G59: 0,45% | H59: 2,44% | I59: 1,28%
...

Sheet Sheet4
A1: main_p_Category_name | B1: Name | C1: main_Category_name | D1: m_DT_detail_all | E1: Số gói
A2: DV_Cắt | B2: [DV] ShineCombo 10 bước Ultra Care 2023 | C2: DV Cắt gội massage (SC) | D2: 2233230263 | E2: 18901 | F2: =D2/E2
A3: DV_Cắt | B3: Combo 1 - First Class 1 | C3: DV Cắt gội massage (SC) | D3: 598116278 | E3: 4410 | F3: =D3/E3
A4: DV_Cắt | B4: combo cắt gội tiện lợi | C4: DV Cắt gội massage (SC) | D4: 199000 | E4: 1 | F4: =D4/E4
A5: DV_Cắt | B5: GenZ - Shine combo | C5: DV Cắt gội massage (SC) | F5: =D5/E5
A6: DV_Cắt | B6: Shine cut Genz | C6: DV Cắt gội massage (SC) | D6: 59000 | E6: 1 | F6: =D6/E6
A7: DV_Cắt | B7: Shinecombo Genz | C7: DV Cắt gội massage (SC) | D7: 79000 | E7: 1 | F7: =D7/E7
A8: DV_Cắt | B8: VH Cắt gội dưỡng sinh Vip | C8: DV Cắt gội massage (SC) | D8: 7547074 | E8: 32 | F8: =D8/E8
A9: DV_Cắt | B9: Combo Cắt gội Kid | C9: DV Cắt KID | D9: 34380000 | E9: 344 | F9: =D9/E9
A10: DV_Cắt | B10: Kid Cắt | C10: DV Cắt KID | D10: 98332500 | E10: 1313 | F10: =D10/E10
A11: DV_Cắt | B11: [DV] Vuốt sáp - sấy tạo kiểu 10k | C11: DV Cắt xả (không gội massage) | D11: 2797000 | E11: 280 | F11: =D11/E11
A12: DV_Cắt | B12: Cắt xả tạo kiểu | C12: DV Cắt xả (không gội massage) | D12: 1137176247 | E12: 12569 | F12: =D12/E12
A13: DV_Cắt_Vip | B13: Cắt Gội Combo 3 - Chăm da | C13: DV Cắt gội chăm sóc S-VIP | D13: 789180510 | E13: 2713 | F13: =D13/E13
A14: DV_Cắt_Vip | B14: Cắt Gội Combo 3 - Dưỡng sinh | C14: DV Cắt gội chăm sóc S-VIP | D14: 210416572 | E14: 711 | F14: =D14/E14
A15: DV_Cắt_Vip | B15: Cắt Gội Combo 5 - Chăm da | C15: DV Cắt gội chăm sóc S-VIP | D15: 399000 | E15: 1 | F15: =D15/E15
A16: DV_Cắt_Vip | B16: Cắt Gội Combo 5 - Dưỡng sinh | C16: DV Cắt gội chăm sóc S-VIP | D16: 80738556 | E16: 176 | F16: =D16/E16
A17: DV_Cắt_Vip | B17: Combo 2 - First Class 2 | C17: DV Cắt gội chăm sóc S-VIP | D17: 496430396 | E17: 2155 | F17: =D17/E17
... A32: DV_chăm sóc | B32: Dịch vụ upgrade combo 3 lên combo 4 (dành riêng Khách đã từng mua topup combo 3) | C32: DV Chăm sóc | D32: 100000 | E32: 1 | F32: =D32/E32
A33: DV_chăm sóc | B33: Khai trương _gội CVG | C33: DV Chăm sóc | F33: =D33/E33
A34: DV_chăm sóc | B34: Nhổ tóc bạc | C34: DV Chăm sóc | D34: 405000 | E34: 9 | F34: =D34/E34
A35: DV_chăm sóc | B35: Tái tạo da đầu - Sạch gàu hết ngứa | C35: DV Chăm sóc | D35: 1372000 | E35: 14 | F35: =D35/E35
A36: DV_chăm sóc | B36: Thư giãn mắt 30k | C36: DV Chăm sóc | F36: =D36/E36
A37: DV_chăm sóc | B37: Trải nghiệm Dầu gội khoa học cao cấp Laborie Derma +10k | C37: DV Chăm sóc | F37: =D37/E37
A38: DV_chăm sóc | B38: Trải nghiệm kem chống nắng Hàn Quốc 10k | C38: DV Chăm sóc | D38: 10000 | E38: 1 | F38: =D38/E38
A39: DV_chăm sóc | B39: Trẻ hóa da đầu - kích thích mọc tóc | C39: DV Chăm sóc | D39: 98000 | E39: 1 | F39: =D39/E39
A40: DV_chăm sóc | B40: VH Gội Vip Dưỡng Sinh | C40: DV Chăm sóc | D40: 796000 | E40: 4 | F40: =D40/E40
A41: DV_chăm sóc | B41: VH Gội Vip Dưỡng Sinh LRT | C41: DV Chăm sóc | D41: 2762666 | E41: 11 | F41: =D41/E41
A42: DV_chăm sóc | B42: [DV] Mặt nạ lạnh Hàn Quốc | C42: Nhóm Da cơ bản (Ngành CS) | D42: 7734167 | E42: 222 | F42: =D42/E42
A43: DV_chăm sóc | B43: [DV] Mặt nạ tẩy da chết sủi bọt cao cấp | C43: Nhóm Da cơ bản (Ngành CS) | D43: 70653198 | E43: 1285 | F43: =D43/E43
A44: DV_chăm sóc | B44: [DV] Tẩy da chết sủi bọt Hàn Quốc | C44: Nhóm Da cơ bản (Ngành CS) | D44: 59393755 | E44: 1700 | F44: =D44/E44
A45: DV_chăm sóc | B45: [DV] Detox tẩy da chết da đầu | C45: Nhóm da đầu (Ngành CS) | D45: 15323073 | E45: 341 | F45: =D45/E45
A46: DV_chăm sóc | B46: Nhổ tóc bạc buổi trưa | C46: Nhóm da đầu (Ngành CS) | D46: 8250000 | E46: 55 | F46: =D46/E46
A47: DV_chăm sóc | B47: [DV] Thư giãn cổ, vai, gáy bạc hà cam ngọt - Thư giãn tai sảng khoái 9 tầng mây 45k | C47: Nhóm Massage (ngành CS) | D47: 5706573 | E47: 127 | F47: =D47/E47
A48: DV_Dưỡng | B48: (2022T) ATS Control Buffer - Khử mùi tạo thơm cho tóc uốn nhuộm 40k | C48: DV Dưỡng | D48: 61135250 | E48: 1530 | F48: =D48/E48
A49: DV_Dưỡng | B49: Phục hồi trẻ hóa Lipid Bond | C49: DV Dưỡng | D49: 82520903 | E49: 571 | F49: =D49/E49
... A70: DV_Nhuộm | B70: NHUỘM THIẾT KẾ PHỤC HỒI CHUYÊN SÂU LIPID BOND 2025 | C70: DV Nhuộm cao cấp (>300k) | D70: 95784290 | E70: 135 | F70: =D70/E70
A71: DV_Nhuộm | B71: Phục Hồi kèm Uốn Nhuộm | C71: DV Nhuộm MOYO | F71: =D71/E71
A72: DV_Nhuộm | B72: (NEW) Nhuộm phủ bạc tiêu chuẩn 199K | C72: DV Nhuộm tiêu chuẩn (<300k) | D72: 46366663 | E72: 233 | F72: =D72/E72
A73: DV_Nhuộm | B73: [DV] Nhuộm đen phủ bạc R&B thảo dược | C73: DV Nhuộm tiêu chuẩn (<300k) | D73: 140589531 | E73: 487 | F73: =D73/E73
A74: DV_Nhuộm | B74: [DV] Tẩy tóc bật tông Ý (1 lần) | C74: DV Nhuộm tiêu chuẩn (<300k) | D74: 13474160 | E74: 53 | F74: =D74/E74
...

Sheet Sheet5
A1: service_id | B1: service_name | C1: service_code | D1: list_price
A2: 1197 | B2: Hấp phục hồi tóc bọc keratin bổ sung lipid cấp độ phân tử 120p | C2: SP01166 | D2: 1749000
A3: 1069 | B3: Gội trải nghiệm 140p | C3: SP01038 | D3: 1199000
A4: 1193 | B4: Uốn/ Nhuộm thiết kế phục hồi 2025 | C4: SP01162 | D4: 1199000
A5: 963 | B5: (NEW) [DV] Premlock Cao cấp 1049K | C5: SP00932 | D5: 1049000
A6: 1068 | B6: Gội trải nghiệm 115p | C6: SP01037 | D6: 999000
A7: 170 | B7: [DV] Premlock 899k | C7: SP00153 | D7: 899000
A8: 1067 | B8: Gội trải nghiệm 90p | C8: SP01036 | D8: 789000
A9: 836 | B9: Ruffled Perm 758k | C9: SP00805 | D9: 758000
A10: 1268 | B10: Combo Vip 2 | C10: SP01237 | D10: 748000
A11: 945 | B11: (NEW) Grass Perm Cao cấp 688K | C11: SP00914 | D11: 688000
A12: 947 | B12: (NEW) Tailor Perm Cao cấp 688K | C12: SP00916 | D12: 688000
A13: 1148 | B13: UỐN THIẾT KẾ PHỤC HỒI CHUYÊN SÂU LIPID BOND 2025 | C13: SP01117 | D13: 686000
... A162: 1288 | B162: Trải nghiệm Dầu gội trị gàu cao cấp Vichy Dercos +10k | C162: SP01257 | D162: 10000

Sheet Bảng giá Relax Spa
A1: salon_id | B1: salon_name | C1: service_id | D1: service_name | E1: Giá dịch vụ
A2: 2 | B2: 346 Khâm Thiên | C2: 610 | D2: (2022T) ATS Control Buffer - Khử mùi tạo thơm cho tóc uốn nhuộm 40k | E2: 40000
A3: 2 | B3: 346 Khâm Thiên | C3: 960 | D3: (NEW) Nhuộm màu thời trang Milano | E3: 369000
A4: 2 | B4: 346 Khâm Thiên | C4: 967 | D4: (NEW) Nhuộm phủ bạc tiêu chuẩn 199K | E4: 227000
A5: 2 | B5: 346 Khâm Thiên | C5: 1009 | D5: (NEW) Uốn/Duỗi/Định hình full đầu tạo form vào nếp tự nhiên | E5: 406000
A6: 2 | B6: 346 Khâm Thiên | C6: 1052 | D6: Combo 1 - First Class 1 | E6: 159000
A7: 2 | B7: 346 Khâm Thiên | C7: 1048 | D7: Combo 4 | E7: 379000
A8: 2 | B8: 346 Khâm Thiên | C8: 1048 | D8: Combo 4 | E8: 389000
A9: 2 | B9: 346 Khâm Thiên | C9: 1070 | D9: Combo Cắt gội Kid | E9: 100000
A10: 2 | B10: 346 Khâm Thiên | C10: 1047 | D10: Cắt Gội Combo 3 - Chăm da | E10: 299000
A11: 2 | B11: 346 Khâm Thiên | C11: 1065 | D11: Cắt Gội Combo 3 - Dưỡng sinh | E11: 299000
A12: 2 | B12: 346 Khâm Thiên | C12: 1064 | D12: Cắt Gội Combo 5 - Dưỡng sinh | E12: 459000
A13: 2 | B13: 346 Khâm Thiên | C13: 891 | D13: Cắt xả tạo kiểu | E13: 90000
... A2389: 302 | B2389: 362 Ngô Gia Tự | C2389: 603 | D2389: Đánh bay mụn cám lột mụn (Full Face) | E2389: 49000

Sheet Sheet7
A1: # | B1: Tên dịch vụ | C1: ServiceId | D1: Category | E1: Giá chuẩn / Khoảng giá
A2: 60 | B2: Uốn/ Nhuộm thiết kế phục hồi 2025 | C2: 1193 | D2: Combo UND | E2: 1.199.000 VNĐ
A3: 55 | B3: Trẻ hóa da đầu - kích thích mọc tóc | C3: 1114 | D3: DV Chăm sóc | E3: 98.000 VNĐ
A4: 65 | B4: VH Gội Vip Dưỡng Sinh | C4: 1258 | D4: DV Chăm sóc | E4: 199.000 VNĐ
A5: 66 | B5: VH Gội Vip Dưỡng Sinh LRT | C5: 1259 | D5: DV Chăm sóc | E5: 259.000 VNĐ
A6: 88 | B6: Đánh bay mụn cám lột mụn (Full Face) | C6: 603 | D6: DV Chăm sóc | E6: 29.000 VNĐ - 49.000 VNĐ
A7: 7 | B7: Combo 2 - First Class 2 | C7: 1053 | D7: DV Cắt gội chăm sóc S-VIP | E7: 229.000 VNĐ - 239.000 VNĐ
A8: 8 | B8: Combo 3 - First Class 3 | C8: 1054 | D8: DV Cắt gội chăm sóc S-VIP | E8: 299.000 VNĐ - 309.000 VNĐ
A9: 9 | B9: Combo 4 | C9: 1048 | D9: DV Cắt gội chăm sóc S-VIP | E9: 379.000 VNĐ - 389.000 VNĐ
A10: 10 | B10: Combo 4- First Class 4 | C10: 1055 | D10: DV Cắt gội chăm sóc S-VIP | E10: 399.000 VNĐ - 409.000 VNĐ
A11: 11 | B11: Combo Best choice | C11: 1194 | D11: DV Cắt gội chăm sóc S-VIP | E11: 299.000 VNĐ
A12: 14 | B12: Cắt Gội Combo 3 - Chăm da | C12: 1047 | D12: DV Cắt gội chăm sóc S-VIP | E12: 279.000 VNĐ - 299.000 VNĐ
A13: 15 | B13: Cắt Gội Combo 3 - Dưỡng sinh | C13: 1065 | D13: DV Cắt gội chăm sóc S-VIP | E13: 299.000 VNĐ
... A69: 72 | B69: [DV] Thư giãn cổ, vai, gáy bạc hà cam ngọt - Thư giãn tai sảng khoái 9 tầng mây 45k | C69: 462 | D69: Nhóm Massage (ngành CS) | E69: 29.000 VNĐ - 45.000 VNĐ

Sheet Điều chỉnh 1 2
A1: GIÁ DỊCH VỤ CẮT XẢ VÀ CÁC DỊCH VỤ RELAX CÓ CẮT
A2: Salon_name | B2: P_Category_name | C2: service_id | D2: service_name | E2: Giá hiện tại | F2: Giá mới sắp triển khai
A3: 145 THT | B3: DV_Cắt | C3: 513 | D3: [DV] ShineCombo 10 bước Ultra Care 2023 | E3: 122000 | F3: 122000 | G3: =VLOOKUP(A3,'Sheet10'!$A:$C,3,0)
A4: 145 THT | B4: DV_Cắt | C4: 891 | D4: Cắt xả tạo kiểu | E4: 94000 | F4: 94000 | G4: =VLOOKUP(A4,'Sheet10'!$A:$C,3,0)
A5: 145 THT | B5: DV_Cắt | C5: 1052 | D5: Combo 1 - First Class 1 | E5: 159000 | F5: 159000 | G5: =VLOOKUP(A5,'Sheet10'!$A:$C,3,0)
A6: 145 THT | B6: DV_Cắt | C6: 1070 | D6: Combo Cắt gội Kid | E6: 100000 | F6: 100000 | G6: =VLOOKUP(A6,'Sheet10'!$A:$C,3,0)
A7: 145 THT | B7: DV_Cắt | C7: 1002 | D7: Kid Cắt | E7: 75000 | F7: 75000 | G7: =VLOOKUP(A7,'Sheet10'!$A:$C,3,0)
A8: 145 THT | B8: DV_Cắt_Vip | C8: 1047 | D8: Cắt Gội Combo 3 - Chăm da | E8: 299000 | F8: 299000 | G8: =VLOOKUP(A8,'Sheet10'!$A:$C,3,0)
A9: 145 THT | B9: DV_Cắt_Vip | C9: 1065 | D9: Cắt Gội Combo 3 - Dưỡng sinh | E9: 299000 | F9: 299000 | G9: =VLOOKUP(A9,'Sheet10'!$A:$C,3,0)
A10: 145 THT | B10: DV_Cắt_Vip | C10: 1049 | D10: Cắt Gội Combo 5 - Chăm da | E10: 399000 | F10: 399000 | G10: =VLOOKUP(A10,'Sheet10'!$A:$C,3,0)
A11: 145 THT | B11: DV_Cắt_Vip | C11: 1064 | D11: Cắt Gội Combo 5 - Dưỡng sinh | E11: 459000 | F11: 459000 | G11: =VLOOKUP(A11,'Sheet10'!$A:$C,3,0)
A12: 145 THT | B12: DV_Cắt_Vip | C12: 1054 | D12: Combo 3 - First Class 3 | E12: 299000 | F12: 299000 | G12: =VLOOKUP(A12,'Sheet10'!$A:$C,3,0)
A13: 145 THT | B13: DV_Cắt_Vip | C13: 1048 | D13: Combo 4 | E13: 389000 | F13: 389000 | G13: =VLOOKUP(A13,'Sheet10'!$A:$C,3,0)
A14: 145 THT | B14: DV_Cắt_Vip | C14: 1046 | D14: Shinecombo 2 | E14: 199000 | F14: 199000 | G14: =VLOOKUP(A14,'Sheet10'!$A:$C,3,0)
... A204: 420 HTP | B204: DV_Cắt_Vip | C204: 1046 | D204: Shinecombo 2 | E204: 199000 | F204: 199000 | G204: =VLOOKUP(A204,'Sheet10'!$A:$C,3,0)

Sheet Điều chỉnh 2 2
A1: GIÁ DỊCH VỤ CẮT XẢ VÀ CÁC DỊCH VỤ RELAX CÓ CẮT
A2: Salon_name | B2: P_Category_name | C2: service_id | D2: service_name | E2: Giá hiện tại | F2: Giá mới sắp triển khai
A3: 255 NAN | G3: =VLOOKUP(A3,'Sheet10'!$A:$C,3,0)
A4: 255 NAN | G4: =VLOOKUP(A4,'Sheet10'!$A:$C,3,0)
A5: 255 NAN | G5: =VLOOKUP(A5,'Sheet10'!$A:$C,3,0)
A6: 255 NAN | G6: =VLOOKUP(A6,'Sheet10'!$A:$C,3,0)
A7: 255 NAN | G7: =VLOOKUP(A7,'Sheet10'!$A:$C,3,0)
A8: 255 NAN | G8: =VLOOKUP(A8,'Sheet10'!$A:$C,3,0)
A9: 255 NAN | G9: =VLOOKUP(A9,'Sheet10'!$A:$C,3,0)
A10: 290 QT TH | G10: =VLOOKUP(A10,'Sheet10'!$A:$C,3,0)
A11: 290 QT TH | G11: =VLOOKUP(A11,'Sheet10'!$A:$C,3,0)
A12: 290 QT TH | G12: =VLOOKUP(A12,'Sheet10'!$A:$C,3,0)
A13: 290 QT TH | G13: =VLOOKUP(A13,'Sheet10'!$A:$C,3,0)
A14: 290 QT TH | G14: =VLOOKUP(A14,'Sheet10'!$A:$C,3,0)
... A72: 451 PVT | G72: =VLOOKUP(A72,'Sheet10'!$A:$C,3,0)
G73: =VLOOKUP(A73,'Sheet10'!$A:$C,3,0)
G74: =VLOOKUP(A74,'Sheet10'!$A:$C,3,0)
G75: =VLOOKUP(A75,'Sheet10'!$A:$C,3,0)
G76: =VLOOKUP(A76,'Sheet10'!$A:$C,3,0)
G77: =VLOOKUP(A77,'Sheet10'!$A:$C,3,0)
G78: =VLOOKUP(A78,'Sheet10'!$A:$C,3,0)
G79: =VLOOKUP(A79,'Sheet10'!$A:$C,3,0)
G80: =VLOOKUP(A80,'Sheet10'!$A:$C,3,0)
G81: =VLOOKUP(A81,'Sheet10'!$A:$C,3,0)
G82: =VLOOKUP(A82,'Sheet10'!$A:$C,3,0)
G83: =VLOOKUP(A83,'Sheet10'!$A:$C,3,0)
G84: =VLOOKUP(A84,'Sheet10'!$A:$C,3,0)
... G177: =VLOOKUP(A177,'Sheet10'!$A:$C,3,0)

Sheet Sheet10
A1: Tên Salon | B1: Tên Supervisor | C1: ID
A2: 10 TP | B2: Phạm Thị Nga | C2: 143
A3: 11 PKT | B3: Phạm Thị Nga | C3: 244
A4: 148 TD | B4: Phạm Thị Nga | C4: 210
A5: 168 NVC | B5: Phạm Thị Nga | C5: 144
A6: 173 TN | B6: Phạm Thị Nga | C6: 250
A7: 186 QT | B7: Phạm Thị Nga | C7: 239
A8: 202 DC | B8: Phạm Thị Nga | C8: 196
A9: 382 NT | B9: Phạm Thị Nga | C9: 20
A10: 39 HBT | B10: Phạm Thị Nga | C10: 200
A11: 50BT4 NPC LD | B11: Phạm Thị Nga | C11: 179
A12: 62 LH | B12: Phạm Thị Nga | C12: 228
A13: 65 CD | B13: Phạm Thị Nga | C13: 197
... A61: 730 TL10 | B61: Cụm HCM | C61: 58

Sheet Chi tiết thay đổi giá dịch vụ n
A1: Tên salon | B1: ID salon | C1: Tên dịch vụ | D1: ID dịch vụ | E1: ID salon | F1: Giá trước ngày 6/3 | G1: Giá thay đổi ngày 6/3 | H1: Note
A2: 103 TN | B2: DV_Uốn | C2: (NEW) Uốn/Duỗi/Định hình full đầu tạo form vào nếp tự nhiên | D2: 1009 | E2: =VLOOKUP(A2,'Sheet10'!$A:$C,3,0) | F2: 416000 | G2: 406000 | H2: Điều chỉnh giá
A3: 103 TN | B3: DV_Uốn | C3: [DV] Uốn Texture con sâu/Uốn Ruffled | D3: 674 | E3: =VLOOKUP(A3,'Sheet10'!$A:$C,3,0) | F3: 564000 | G3: 554000 | H3: Điều chỉnh giá
A4: 103 TN | B4: DV_Uốn | C4: UỐN THIẾT KẾ PHỤC HỒI CHUYÊN SÂU LIPID BOND 2025 | D4: 1148 | E4: =VLOOKUP(A4,'Sheet10'!$A:$C,3,0) | F4: 739000 | G4: 729000 | H4: Điều chỉnh giá
A5: 103 TN | B5: DV_Uốn | C5: Uốn định hình nếp tóc cao cấp (K-Perm Collection) | D5: 952 | E5: =VLOOKUP(A5,'Sheet10'!$A:$C,3,0) | F5: 512000 | G5: 502000 | H5: Điều chỉnh giá
A6: 264 LLQ | B6: DV_Cắt | C6: Cắt xả tạo kiểu | D6: 891 | E6: =VLOOKUP(A6,'Sheet10'!$A:$C,3,0) | F6: 103000 | G6: 94000 | H6: Điều chỉnh giá
A7: 264 LLQ | B7: DV_Cắt | C7: Kid Cắt | D7: 1002 | E7: =VLOOKUP(A7,'Sheet10'!$A:$C,3,0) | F7: 84000 | G7: 75000 | H7: Điều chỉnh giá
A8: 264 LLQ | B8: DV_Cắt_Vip | C8: Cắt Gội Combo 3 - Chăm da | D8: 1047 | E8: =VLOOKUP(A8,'Sheet10'!$A:$C,3,0) | F8: 308000 | G8: 299000 | H8: Điều chỉnh giá
A9: 264 LLQ | B9: DV_Cắt_Vip | C9: Cắt Gội Combo 5 - Dưỡng sinh | D9: 1064 | E9: =VLOOKUP(A9,'Sheet10'!$A:$C,3,0) | F9: 468000 | G9: 459000 | H9: Điều chỉnh giá
A10: 264 LLQ | B10: DV_Cắt_Vip | C10: Combo 4 | D10: 1048 | E10: =VLOOKUP(A10,'Sheet10'!$A:$C,3,0) | F10: 398000 | G10: 389000 | H10: Điều chỉnh giá
A11: 264 LLQ | B11: DV_Cắt_Vip | C11: Shinecombo 2 | D11: 1046 | E11: =VLOOKUP(A11,'Sheet10'!$A:$C,3,0) | F11: 208000 | G11: 199000 | H11: Điều chỉnh giá
A12: 451 PVT | B12: DV_Cắt | C12: Cắt xả tạo kiểu | D12: 891 | E12: =VLOOKUP(A12,'Sheet10'!$A:$C,3,0) | F12: 102000 | G12: 94000 | H12: Điều chỉnh giá
A13: 451 PVT | B13: DV_Cắt | C13: Kid Cắt | D13: 1002 | E13: =VLOOKUP(A13,'Sheet10'!$A:$C,3,0) | F13: 83000 | G13: 75000 | H13: Điều chỉnh giá
... A42: 90 NH | B42: DV_Cắt_Vip | C42: Shinecombo 2 | D42: 1046 | E42: =VLOOKUP(A42,'Sheet10'!$A:$C,3,0) | F42: 204000 | G42: 199000 | H42: Điều chỉnh giá

Sheet Bảng giá Relax điều chỉnh ngày 
A1: Tên Salon | B1: ID Salon | C1: CPI | D1: CPI Level | E1: EPI | F1: EPI Level | G1: CR thay đổi (%) | H1: Nhóm đề xuất | I1: Logic / Benchmark cụm
A2: 264 LLQ | B2: 192 | C2: 0.57 | D2: Trung | E2: 0.43 | F2: Trung | G2: -5.7 | H2: Back ngay | I2: Tăng đồng loạt +18K, vượt xa cụm (168 NVC chỉ +9K). Back về +9K chuẩn cụm 29
A3: 7 DTP LA | B3: 199 | C3: 0.53 | D3: Trung | E3: 0.38 | F3: Thấp | G3: -10.7 | H3: Back ngay | I3: Salon độc lập Long An, CPI 0.53 Trung + EPI 0.38 Thấp. DV phụ tăng quá cao cho thị trường tỉnh
A4: 451 PVT | B4: 52 | C4: 0.54 | D4: Trung | E4: 0.31 | F4: Thấp | G4: -5.1 | H4: Back ngay | I4: 1371 PVT cùng cụm chỉ tăng 1 DV (6K) → OK. 451 PVT tăng 20 DV TB 25K → quá aggressive
A5: 80 TP TH | B5: 232 | C5: 0.52 | D5: Trung | E5: 0.41 | F5: Thấp | G5: -14.1 | H5: Back ngay | I5: Thanh Hóa thị trường nhạy giá. DV phụ tăng 14K-68K vượt khả năng chịu giá
A6: 708 LTT | B6: 47 | C6: 0.56 | D6: Trung | E6: 0.36 | F6: Thấp | G6: -8.8 | H6: Back ngay | I6: 32 NAT cùng cụm EPI 0.42 → CR +10%. 708 LTT EPI 0.36 → khách ít sẵn sàng chi
A7: 346 KT | B7: 2 | C7: 0.66 | D7: Cao | E7: 0.47 | F7: Cao | G7: -6.9 | H7: Back ngay | I7: CPI 0.66 Cao, Cắt Gội C3 CD là DV nhạy nhất
A8: 575 AC | B8: 21 | C8: 0.64 | D8: Cao | E8: 0.45 | F8: Trung | G8: -12.9 | H8: Back chọn lọc | I8: 99 TSN cùng cụm, cùng mức tăng → CR OK. Khác biệt do cơ cấu khách
A9: 148 TD | B9: 210 | C9: 0.64 | D9: Cao | E9: 0.36 | F9: Thấp | G9: -5.3 | H9: Back chọn lọc | I9: 173 TN cùng cụm chỉ tăng 2K → CR -1.4%. 148 TD DV phụ cao hơn
A10: 76 PVH | B10: 106 | C10: 0.5 | D10: Trung | E10: 0.37 | F10: Thấp | G10: -3.9 | H10: Back chọn lọc | I10: CPI 0.50 thấp nhất cụm 25, nhạy giá hơn 32 NAT (0.56)
A11: 11 PKT | B11: 244 | C11: 0.45 | D11: Trung | E11: 0.44 | F11: Trung | G11: -27.5 | H11: Back chọn lọc | I11: CPI 0.45 thấp nhất cụm 30. Khách nhạy giá hơn
A12: 236 DBT | B12: 141 | C12: 0.65 | D12: Cao | E12: 0.42 | F12: Trung | G12: -3.7 | H12: Theo dõi | I12: Mức tăng thấp 3K. Giảm do Gội C2 & SC10 giá không đổi
A13: 186 DTH | B13: 182 | C13: 0.63 | D13: Cao | E13: 0.44 | F13: Trung | G13: -2.9 | H13: Theo dõi | I13: Mức tăng 1K. Giảm nhẹ, tự phục hồi
... A17: 68 LN NA | B17: 240 | C17: 0.45 | D17: Trung | E17: 0.39 | F17: Thấp | G17: -10.9 | H17: Back ngay | I17: Ghép cụm 10 với 58 NVC NA (cùng Nghệ An). Rule 8: điều chỉnh giá = 58 NVC. DV Cắt -9K so với giá cũ, DV Gội = giá cũ
A19: Tên Salon | B19: ID Salon | C19: Tên dịch vụ | D19: ID DV | E19: Nhóm ngành | F19: Giá cũ (trước 14/3) | G19: Giá mới từ 14/3 | H19: Giá điều chỉnh từ 24/3 | I19: Chênh lệch (đề xuất vs hiện tại)
A20: 11 PKT | B20: 244 | C20: Cắt Gội Combo 3 - Chăm da | D20: 1047 | E20: DV_Cắt_Vip | F20: 305000 | G20: 317000 | H20: 309000 | I20: -8000 | J20: =B20&D20 | K20: 309000
A21: 11 PKT | B21: 244 | C21: Gội Combo 3 - Chăm da | D21: 1059 | E21: DV_Gội | F21: 239000 | G21: 249000 | H21: 243000 | I21: -6000 | J21: =B21&D21 | K21: 243000
A22: 11 PKT | B22: 244 | C22: Gội Combo 4 | D22: 1060 | E22: DV_Gội | F22: 289000 | G22: 302000 | H22: 289000 | I22: -13000 | J22: =B22&D22 | K22: 289000
A23: 11 PKT | B23: 244 | C23: Gội dưỡng sinh cổ vai gáy | D23: 867 | E23: DV_Gội | F23: 99000 | G23: 103000 | H23: 99000 | I23: -4000 | J23: =B23&D23 | K23: 99000
A24: 11 PKT | B24: 244 | C24: Gội trải nghiệm 75p | D24: 1066 | E24: DV_Gội | F24: 589000 | G24: 613000 | H24: 594000 | I24: -19000 | J24: =B24&D24 | K24: 594000
A25: 11 PKT | B25: 244 | C25: Shinecombo 2 | D25: 1046 | E25: DV_Cắt_Vip | F25: 205000 | G25: 213000 | H25: 209000 | I25: -4000 | J25: =B25&D25 | K25: 209000
A26: 11 PKT | B26: 244 | C26: [NEW] Gội dưỡng sinh | D26: 940 | E26: DV_Gội | F26: 59000 | G26: 61000 | H26: 59000 | I26: -2000 | J26: =B26&D26 | K26: 59000
A27: 11 PKT | B27: 244 | C27: [NEW] Gội dưỡng sinh cổ vai gáy và chăm sóc da | D27: 930 | E27: DV_Gội | F27: 139000 | G27: 145000 | H27: 139000 | I27: -6000 | J27: =B27&D27 | K27: 139000
A28: 148 TD | B28: 210 | C28: Combo 4 | D28: 1048 | E28: DV_Cắt_Vip | F28: 391000 | G28: 407000 | H28: 399000 | I28: -8000 | J28: =B28&D28 | K28: 399000
A29: 148 TD | B29: 210 | C29: Gội Combo 2 | D29: 1058 | E29: DV_Gội | F29: 159000 | G29: 166000 | H29: 162000 | I29: -4000 | J29: =B29&D29 | K29: 162000
A30: 148 TD | B30: 210 | C30: Gội Combo 4 | D30: 1060 | E30: DV_Gội | F30: 289000 | G30: 302000 | H30: 297000 | I30: -5000 | J30: =B30&D30 | K30: 297000
A31: 148 TD | B31: 210 | C31: Gội trải nghiệm 75p | D31: 1066 | E31: DV_Gội | F31: 589000 | G31: 614000 | H31: 597000 | I31: -17000 | J31: =B31&D31 | K31: 597000
... A135: 80 TP TH | B135: 232 | C135: [NEW] Gội dưỡng sinh cổ vai gáy và chăm sóc da | D135: 930 | E135: DV_Gội | F135: 139000 | G135: 148000 | H135: 146000 | I135: -2000 | J135: =B135&D135 | K135: 146000
A136: 39 HBT | B136: 200 | C136: Combo 4 | D136: 1048 | E136: DV_Cắt_Vip | F136: 395000 | G136: 411000 | H136: 395000 | I136: -8000
A137: 39 HBT | B137: 200 | C137: Gội Combo 2 | D137: 1058 | E137: DV_Gội | F137: 159000 | G137: 165000 | H137: 159000 | I137: -6000
A138: 39 HBT | B138: 200 | C138: Gội Combo 3 - Chăm da | D138: 1059 | E138: DV_Gội | F138: 239000 | G138: 249000 | H138: 239000 | I138: -10000
A139: 39 HBT | B139: 200 | C139: Gội Combo 4 | D139: 1060 | E139: DV_Gội | F139: 289000 | G139: 302000 | H139: 289000 | I139: -13000
A140: 39 HBT | B140: 200 | C140: Gội combo 3 - Dưỡng sinh | D140: 934 | E140: DV_Gội | F140: 229000 | G140: 238000 | H140: 229000 | I140: -9000
A141: 39 HBT | B141: 200 | C141: Gội dưỡng sinh cổ vai gáy | D141: 867 | E141: DV_Gội | F141: 99000 | G141: 103000 | H141: 99000 | I141: -4000
A142: 39 HBT | B142: 200 | C142: Gội trải nghiệm 115p | D142: 1068 | E142: DV_Gội | F142: 999000 | G142: 1039000 | H142: 999000 | I142: -40000
A143: 39 HBT | B143: 200 | C143: Gội trải nghiệm 140p | D143: 1069 | E143: DV_Gội | F143: 1199000 | G143: 1247000 | H143: 1199000 | I143: -48000
A144: 39 HBT | B144: 200 | C144: Gội trải nghiệm 75p | D144: 1066 | E144: DV_Gội | F144: 589000 | G144: 613000 | H144: 589000 | I144: -24000
A145: 39 HBT | B145: 200 | C145: Gội trải nghiệm 90p | D145: 1067 | E145: DV_Gội | F145: 789000 | G145: 821000 | H145: 789000 | I145: -32000
A146: 39 HBT | B146: 200 | C146: Shinecombo 2 | D146: 1046 | E146: DV_Cắt_Vip | F146: 205000 | G146: 213000 | H146: 205000 | I146: -3000
A147: 39 HBT | B147: 200 | C147: [NEW] Gội dưỡng sinh cổ vai gáy và chăm sóc da | D147: 930 | E147: DV_Gội | F147: 139000 | G147: 145000 | H147: 139000 | I147: -6000
